Workbook

Sheet Extended Profile (EP)
A1: Criteria | B1: Metric Num | C1: Metric Description
A2: 1 Student: | B2: 1.1 | C2: Number of students year wise during the last five years
B3: Year
B4: Number
A5: 2 Teachers: | B5: 2.1 | C5: Number of full time teachers during the last five years (Without repeat count):
B6: 2.2 | C6: Number of full time teachers year wise during the last five years
B7: Year
B8: Number
A9: 3. Expenditure: | B9: 3.1 | C9: Expenditure excluding salary component year wise during the last five years (INR in lakhs)
B10: Year
B11: INR in Lakhs

Sheet Response Score Calc.
A2: S. No | B2: Criteria © | C2: Key Indicator (KI) | D2: Metric (M) Type | E2: Metric (M) Num | F2: Metric (M) Description | G2: M Wt | H2: HEI I/P (Response) | I2: P Response Score
A3: =SUBTOTAL(3,$B$3:B3) -> 1 | B3: 1. Curricular Aspects | C3: 1.2 Academic Flexibility | D3: QnM | E3: 1.2.1 | F3: Number of Add on /Certificate/ Value added programs offered during the last five years | G3: 15
A4: =SUBTOTAL(3,$B$3:B4) -> 2 | B4: 1. Curricular Aspects | C4: 1.2 Academic Flexibility | D4: QnM | E4: 1.2.2 | F4: Average percentage of students enrolled in Certificate/ Add-on/ Value added programs as against the total number of students during the last five years | G4: 15
A5: =SUBTOTAL(3,$B$3:B5) -> 3 | B5: 1. Curricular Aspects | C5: 1.3 Curriculum Enrichment | D5: QnM | E5: 1.3.2 | F5: Percentage of students undertaking project work/field work/internships (Data for the latest completed academic year) | G5: 20
A6: =SUBTOTAL(3,$B$3:B6) -> 4 | B6: 1. Curricular Aspects | C6: 1.4 Feedback System | D6: QnM | E6: 1.4.1 | F6: Institution obtains feedback on the academic performance and ambience of the institution from various stakeholders, such as Students, Teachers, Employers, Alumni etc. and action taken report on the feedback is made available on institutional website (Yes or No) | G6: 20
A7: =SUBTOTAL(3,$B$3:B7) -> 5 | B7: 2. Teaching-Learning and Evaluation | C7: 2.1 Student Enrolment and Profile | D7: QnM | E7: 2.1.1 | F7: Enrolment percentage | G7: 20
A8: =SUBTOTAL(3,$B$3:B8) -> 6 | B8: 2. Teaching-Learning and Evaluation | C8: 2.1 Student Enrolment and Profile | D8: QnM | E8: 2.1.2 | F8: Percentage of seats filled against seats reserved for various categories (SC, ST, OBC, Divyangjan, etc. as per applicable reservation policy during the last five years ( exclusive of supernumerary seats) | G8: 20
A9: =SUBTOTAL(3,$B$3:B9) -> 7 | B9: 2. Teaching-Learning and Evaluation | C9: 2.2 Student Teacher Ratio | D9: QnM | E9: 2.2.1 | F9: Student- Full time teacher ratio (Data for the latest completed academic year) | G9: 40
A10: =SUBTOTAL(3,$B$3:B10) -> 8 | B10: 2. Teaching-Learning and Evaluation | C10: 2.4 Teacher Profile and Quality | D10: QnM | E10: 2.4.1 | F10: Percentage of full time teachers against sanctioned posts during the last five years | G10: 15
A11: =SUBTOTAL(3,$B$3:B11) -> 9 | B11: 2. Teaching-Learning and Evaluation | C11: 2.4 Teacher Profile and Quality | D11: QnM | E11: 2.4.2 | F11: Percentage of full time teachers with NET/SET/SLET/ Ph. D. / D.M. / M.Ch. / D.N.B Super speciality / D.Sc. / D.Litt. during the last five years (consider only highest degree for count) | G11: 25
A12: =SUBTOTAL(3,$B$3:B12) -> 10 | B12: 2. Teaching-Learning and Evaluation | C12: 2.6 Student Performance and Learning Outcomes | D12: QnM | E12: 2.6.2 | F12: Pass percentage of Students during last five years | G12: 45
A13: =SUBTOTAL(3,$B$3:B13) -> 11 | B13: 2. Teaching-Learning and Evaluation | C13: 2.7 Student Satisfaction Survey | D13: QnM | E13: 2.7.1 | F13: Online student satisfaction survey regarding to teaching learning process. (Online survey to be conducted) | G13: 60
A14: =SUBTOTAL(3,$B$3:B14) -> 12 | B14: 3. Research, Innovations and Extension | C14: 3.1 Resource Mobilization for Research | D14: QnM | E14: 3.1.1 | F14: Grants received from Government and non-governmental agencies for research projects, endowments, Chairs in the institution during the last five years (INR in Lakhs) | G14: 10
... A36: =SUBTOTAL(3,$B$3:B36) -> 34 | B36: 7. Institutional Values and Best Practices | C36: 7.1 Institutional Values and Social Responsibilities | D36: QnM | E36: 7.1.3 | F36: Quality audits on environment and energy regularly undertaken by the Institution. The institutional environment and energy initiatives are confirmed through the following 1. Green audit / Environment audit 2. Energy audit 3. Clean and green campus initiatives 4. Beyond the campus environmental promotion activities | G36: 10

Sheet Affiliated(55m)
J1: RESPONSE | K1: Affiliated
A2: S. No | B2: Criteria © | C2: Key Indicator (KI) | D2: Metric (M) Type | E2: Metric (M) Num | F2: Metric (M) Description | G2: M Wt | H2: KI Wt | I2: © Wt | J2: Institute Name | K2: Metric Grade scale (0-4) | L2: M wise weighted Grade points | M2: KIwise weighted Grade points | N2: KIwise weighted Grade points Average | O2: ©Wise Weighted Average | P2: ©Wise Weighted Grade Point Average
A3: 1 | B3: 1. Curricular Aspects | C3: 1.1 Curriculum Planning and Implementation | D3: QlM | E3: 1.1.1 | F3: The Institution ensures effective curriculum planning and delivery through a well-planned and documented process including Academic calendar and conduct of continuous internal Assessment | G3: 20 | H3: 20 | I3: 100 | K3: =IF(J3>80,4,IF(AND(J3<=80,J3>60),3,IF(AND(J3<=60,J3>40),2,IF(AND(J3<=40,J3>20),1,IF(J3<=20,0))))) -> 0 | L3: =K3*G3 -> 0 | M3: =L3 -> 0 | N3: =M3/H3 -> 0 | O3: =SUM(M3:M8) -> 80 | P3: =O3/I3 -> 0.8
A4: 2 | B4: 1. Curricular Aspects | C4: 1.2 Academic Flexibility | D4: QnM | E4: 1.2.1 | F4: Number of Add on /Certificate/ Value added programs offered during the last five years | G4: 15 | H4: 30 | J4: 4 | K4: =IF(J4>80,4,IF(AND(J4<=80,J4>60),3,IF(AND(J4<=60,J4>40),2,IF(AND(J4<=40,J4>20),1,IF(J4<=20,0))))) -> 0 | L4: =K4*G4 -> 0 | M4: =L4+L5 -> 0 | N4: =M4/H4 -> 0
A5: 3 | B5: 1. Curricular Aspects | C5: 1.2 Academic Flexibility | D5: QnM | E5: 1.2.2 | F5: Average percentage of students enrolled in Certificate/ Add-on/ Value added programs as against the total number of students during the last five years | G5: 15 | J5: 1.29 | K5: =IF(J5>80,4,IF(AND(J5<=80,J5>60),3,IF(AND(J5<=60,J5>40),2,IF(AND(J5<=40,J5>20),1,IF(J5<=20,0))))) -> 0 | L5: =K5*G5 -> 0
A6: 4 | B6: 1. Curricular Aspects | C6: 1.3 Curriculum Enrichment | D6: QlM | E6: 1.3.1 | F6: Institution integrates crosscutting issues relevant to Professional Ethics, Gender, Human Values, Environment and Sustainability into the Curriculum | G6: 10 | H6: 30 | K6: =IF(J6>80,4,IF(AND(J6<=80,J6>60),3,IF(AND(J6<=60,J6>40),2,IF(AND(J6<=40,J6>20),1,IF(J6<=20,0))))) -> 0 | L6: =K6*G6 -> 0 | M6: =L6+L7 -> 0 | N6: =M6/H6 -> 0
A7: 5 | B7: 1. Curricular Aspects | C7: 1.3 Curriculum Enrichment | D7: QnM | E7: 1.3.2 | F7: Percentage of students undertaking project work/field work/internships (Data for the latest completed academic year) | G7: 20 | J7: 17.77 | K7: =IF(J7>80,4,IF(AND(J7<=80,J7>60),3,IF(AND(J7<=60,J7>40),2,IF(AND(J7<=40,J7>20),1,IF(J7<=20,0))))) -> 0 | L7: =K7*G7 -> 0
A8: 6 | B8: 1. Curricular Aspects | C8: 1.4 Feedback System | D8: QnM | E8: 1.4.1 | F8: Institution obtains feedback on the academic performance and ambience of the institution from various stakeholders, such as Students, Teachers, Employers, Alumni etc. and action taken report on the feedback is made available on institutional website (Yes or No) | G8: 20 | H8: 20 | J8: Yes | K8: =IF(EXACT(J8,"Yes"),4) -> 4 | L8: =K8*G8 -> 80 | M8: =L8 -> 80 | N8: =M8/H8 -> 4
A9: 7 | B9: 2. Teaching-Learning and Evaluation | C9: 2.1 Student Enrolment and Profile | D9: QnM | E9: 2.1.1 | F9: Enrolment percentage | G9: 20 | H9: 40 | I9: 350 | J9: 68.39 | K9: =IF(J9>80,4,IF(AND(J9<=80,J9>60),3,IF(AND(J9<=60,J9>40),2,IF(AND(J9<=40,J9>20),1,IF(J9<=20,0))))) -> 3 | L9: =K9*G9 -> 60 | M9: =L9+L10 -> 140 | N9: =M9/H9 -> 3.5 | O9: =SUM(M9:M18) -> 585 | P9: =O9/I9 -> 1.6714286
A10: 8 | B10: 2. Teaching-Learning and Evaluation | C10: 2.1 Student Enrolment and Profile | D10: QnM | E10: 2.1.2 | F10: Percentage of seats filled against seats reserved for various categories (SC, ST, OBC, Divyangjan, etc. as per applicable reservation policy during the last five years ( exclusive of supernumerary seats) | G10: 20 | J10: 96.16 | K10: =IF(J10>80,4,IF(AND(J10<=80,J10>60),3,IF(AND(J10<=60,J10>40),2,IF(AND(J10<=40,J10>20),1,IF(J10<=20,0))))) -> 4 | L10: =K10*G10 -> 80
A11: 9 | B11: 2. Teaching-Learning and Evaluation | C11: 2.2 Student Teacher Ratio | D11: QnM | E11: 2.2.1 | F11: Student- Full time teacher ratio (Data for the latest completed academic year) | G11: 40 | H11: 40 | J11: 60.5 | K11: =IF(J11>80,4,IF(AND(J11<=80,J11>60),3,IF(AND(J11<=60,J11>40),2,IF(AND(J11<=40,J11>20),1,IF(J11<=20,0))))) -> 3 | L11: =K11*G11 -> 120 | M11: =L11 -> 120 | N11: =M11/H11 -> 3
A12: 10 | B12: 2. Teaching-Learning and Evaluation | C12: 2.3 Teaching Learning Process | D12: QlM | E12: 2.3.1 | F12: Student centric methods, such as experiential learning, participative learning and problem solving methodologies are used for enhancing learning experiences using ICT tools | G12: 40 | H12: 40 | K12: =IF(J12>80,4,IF(AND(J12<=80,J12>60),3,IF(AND(J12<=60,J12>40),2,IF(AND(J12<=40,J12>20),1,IF(J12<=20,0))))) -> 0 | L12: =K12*G12 -> 0 | M12: =L12 -> 0 | N12: =M12/H12 -> 0
A13: 11 | B13: 2. Teaching-Learning and Evaluation | C13: 2.4 Teacher Profile and Quality | D13: QnM | E13: 2.4.1 | F13: Percentage of full time teachers against sanctioned posts during the last five years | G13: 15 | H13: 40 | J13: 100 | K13: =IF(J13>80,4,IF(AND(J13<=80,J13>60),3,IF(AND(J13<=60,J13>40),2,IF(AND(J13<=40,J13>20),1,IF(J13<=20,0))))) -> 4 | L13: =K13*G13 -> 60 | M13: =L13+L14 -> 85 | N13: =M13/H13 -> 2.125
A14: 12 | B14: 2. Teaching-Learning and Evaluation | C14: 2.4 Teacher Profile and Quality | D14: QnM | E14: 2.4.2 | F14: Percentage of full time teachers with NET/SET/SLET/ Ph. D. / D.M. / M.Ch. / D.N.B Super speciality / D.Sc. / D.Litt. during the last five years (consider only highest degree for count) | G14: 25 | J14: 23.85 | K14: =IF(J14>80,4,IF(AND(J14<=80,J14>60),3,IF(AND(J14<=60,J14>40),2,IF(AND(J14<=40,J14>20),1,IF(J14<=20,0))))) -> 1 | L14: =K14*G14 -> 25
A15: 13 | B15: 2. Teaching-Learning and Evaluation | C15: 2.5 Evaluation Process and Reforms | D15: QlM | E15: 2.5.1 | F15: Mechanism of internal/ external assessment is transparent and the grievance redressal system is time- bound and efficient | G15: 40 | H15: 40 | K15: =IF(J15>80,4,IF(AND(J15<=80,J15>60),3,IF(AND(J15<=60,J15>40),2,IF(AND(J15<=40,J15>20),1,IF(J15<=20,0))))) -> 0 | L15: =K15*G15 -> 0 | M15: =L15 -> 0 | N15: =M15/H15 -> 0
A16: 14 | B16: 2. Teaching-Learning and Evaluation | C16: 2.6 Student Performance and Learning Outcomes | D16: QlM | E16: 2.6.1 | F16: Programme Outcomes (POs) and Course Outcomes (COs) for all Programmes offered by the institution are stated and displayed on website and attainment of POs and COs are evaluated | G16: 45 | H16: 90 | K16: =IF(J16>80,4,IF(AND(J16<=80,J16>60),3,IF(AND(J16<=60,J16>40),2,IF(AND(J16<=40,J16>20),1,IF(J16<=20,0))))) -> 0 | L16: =K16*G16 -> 0 | M16: =L16+L17 -> 180 | N16: =M16/H16 -> 2
A17: 15 | B17: 2. Teaching-Learning and Evaluation | C17: 2.6 Student Performance and Learning Outcomes | D17: QnM | E17: 2.6.2 | F17: Pass percentage of Students during last five years | G17: 45 | J17: 98.36 | K17: =IF(J17>80,4,IF(AND(J17<=80,J17>60),3,IF(AND(J17<=60,J17>40),2,IF(AND(J17<=40,J17>20),1,IF(J17<=20,0))))) -> 4 | L17: =K17*G17 -> 180
A18: 16 | B18: 2. Teaching-Learning and Evaluation | C18: 2.7 Student Satisfaction Survey | D18: QnM | E18: 2.7.1 | F18: Online student satisfaction survey regarding to teaching learning process. (Online survey to be conducted) | G18: 60 | H18: 60 | J18: 29 | K18: =IF(J18>80,4,IF(AND(J18<=80,J18>60),3,IF(AND(J18<=60,J18>40),2,IF(AND(J18<=40,J18>20),1,IF(J18<=20,0))))) -> 1 | L18: =K18*G18 -> 60 | M18: =L18 -> 60 | N18: =M18/H18 -> 1
A19: 17 | B19: 3. Research, Innovations and Extension | C19: 3.1 Resource Mobilization for Research | D19: QnM | E19: 3.1.1 | F19: Grants received from Government and non-governmental agencies for research projects, endowments, Chairs in the institution during the last five years (INR in Lakhs) | G19: 10 | H19: 10 | I19: 110 | J19: 0 | K19: =IF(J19>80,4,IF(AND(J19<=80,J19>60),3,IF(AND(J19<=60,J19>40),2,IF(AND(J19<=40,J19>20),1,IF(J19<=20,0))))) -> 0 | L19: =K19*G19 -> 0 | M19: =L19 -> 0 | N19: =M19/H19 -> 0 | O19: =SUM(M19:M27) -> 115 | P19: =O19/I19 -> 1.0454545
A20: 18 | B20: 3. Research, Innovations and Extension | C20: 3.2 Innovation Ecosystem | D20: QlM | E20: 3.2.1 | F20: Institution has created an ecosystem for innovations and has initiatives for creation and transfer of knowledge (patents filed, published, incubation centre facilities in the HEI to be considered) | G20: 10 | H20: 15 | K20: =IF(J20>80,4,IF(AND(J20<=80,J20>60),3,IF(AND(J20<=60,J20>40),2,IF(AND(J20<=40,J20>20),1,IF(J20<=20,0))))) -> 0 | L20: =K20*G20 -> 0 | M20: =L20+L21 -> 5 | N20: =M20/H20 -> 0.33333333
A21: 19 | B21: 3. Research, Innovations and Extension | C21: 3.2 Innovation Ecosystem | D21: QnM | E21: 3.2.2 | F21: Number of workshops/seminars conducted on Research Methodology, Intellectual Property Rights (IPR) and entrepreneurship during the last five years | G21: 5 | J21: 26 | K21: =IF(J21>80,4,IF(AND(J21<=80,J21>60),3,IF(AND(J21<=60,J21>40),2,IF(AND(J21<=40,J21>20),1,IF(J21<=20,0))))) -> 1 | L21: =K21*G21 -> 5
A22: 20 | B22: 3. Research, Innovations and Extension | C22: 3.3 Research Publications and Awards | D22: QnM | E22: 3.3.1 | F22: Number of research papers per teachers in the Journals notified on UGC website during the last five years | G22: 10 | H22: 25 | J22: 11.54 | K22: =IF(J22>80,4,IF(AND(J22<=80,J22>60),3,IF(AND(J22<=60,J22>40),2,IF(AND(J22<=40,J22>20),1,IF(J22<=20,0))))) -> 0 | L22: =K22*G22 -> 0 | M22: =L22+L23 -> 30 | N22: =M22/H22 -> 1.2
A23: 21 | B23: 3. Research, Innovations and Extension | C23: 3.3 Research Publications and Awards | D23: QnM | E23: 3.3.2 | F23: Number of books and chapters in edited volumes/books published and papers published in national/ international conference proceedings per teacher during last five years | G23: 15 | J23: 53.85 | K23: =IF(J23>80,4,IF(AND(J23<=80,J23>60),3,IF(AND(J23<=60,J23>40),2,IF(AND(J23<=40,J23>20),1,IF(J23<=20,0))))) -> 2 | L23: =K23*G23 -> 30
A24: 22 | B24: 3. Research, Innovations and Extension | C24: 3.4 Extension Activities | D24: QlM | E24: 3.4.1 | F24: Extension activities are carried out in the neighbourhood community, sensitizing students to social issues, for their holistic development, and impact thereof during the last five years. | G24: 10 | H24: 40 | K24: =IF(J24>80,4,IF(AND(J24<=80,J24>60),3,IF(AND(J24<=60,J24>40),2,IF(AND(J24<=40,J24>20),1,IF(J24<=20,0))))) -> 0 | L24: =K24*G24 -> 0 | M24: =SUM(L24:L26) -> 80 | N24: =M24/H24 -> 2
A25: 23 | B25: 3. Research, Innovations and Extension | C25: 3.4 Extension Activities | D25: QlM | E25: 3.4.2 | F25: Awards and recognitions received for extension activities from government / government recognised bodies | G25: 10 | K25: =IF(J25>80,4,IF(AND(J25<=80,J25>60),3,IF(AND(J25<=60,J25>40),2,IF(AND(J25<=40,J25>20),1,IF(J25<=20,0))))) -> 0 | L25: =K25*G25 -> 0
A26: 24 | B26: 3. Research, Innovations and Extension | C26: 3.4 Extension Activities | D26: QnM | E26: 3.4.3 | F26: Number of extension and outreach Programmes conducted by the institution through NSS/ NCC/ Red Cross/ YRC etc., (including the programmes such as Swachh Bharat, AIDS awareness, Gender issues etc. )and/or those organised in collaboration with industry, community and NGOs during the last five years | G26: 20 | J26: 90 | K26: =IF(J26>80,4,IF(AND(J26<=80,J26>60),3,IF(AND(J26<=60,J26>40),2,IF(AND(J26<=40,J26>20),1,IF(J26<=20,0))))) -> 4 | L26: =K26*G26 -> 80
A27: 25 | B27: 3. Research, Innovations and Extension | C27: 3.5 Collaboration | D27: QnM | E27: 3.5.1 | F27: The number of MoUs, collaborations/linkages for Faculty exchange, Student exchange, Internship, Field trip, On-the- job training, research and other academic activities during the last five years | G27: 20 | H27: 20 | J27: 1 | K27: =IF(J27>80,4,IF(AND(J27<=80,J27>60),3,IF(AND(J27<=60,J27>40),2,IF(AND(J27<=40,J27>20),1,IF(J27<=20,0))))) -> 0 | L27: =K27*G27 -> 0 | M27: =L27 -> 0 | N27: =M27/H27 -> 0
A28: 26 | B28: 4. Infrastructure and Learning Resources | C28: 4.1 Physical Facilities | D28: QlM | E28: 4.1.1 | F28: Availability of adequate infrastructure and physical facilities viz., classrooms, laboratories, ICT facilities, cultural activities, gymnasium, yoga centre etc. in the institution | G28: 20 | H28: 30 | I28: 100 | K28: =IF(J28>80,4,IF(AND(J28<=80,J28>60),3,IF(AND(J28<=60,J28>40),2,IF(AND(J28<=40,J28>20),1,IF(J28<=20,0))))) -> 0 | L28: =K28*G28 -> 0 | M28: =L28+L29 -> 40 | N28: =M28/H28 -> 1.3333333 | O28: =SUM(M28:M33) -> 60 | P28: =O28/I28 -> 0.6
A29: 27 | B29: 4. Infrastructure and Learning Resources | C29: 4.1 Physical Facilities | D29: QnM | E29: 4.1.2 | F29: Percentage of expenditure, excluding salary for infrastructure augmentation during last five years(INR in Lakhs) | G29: 10 | J29: 100 | K29: =IF(J29>80,4,IF(AND(J29<=80,J29>60),3,IF(AND(J29<=60,J29>40),2,IF(AND(J29<=40,J29>20),1,IF(J29<=20,0))))) -> 4 | L29: =K29*G29 -> 40
A30: 28 | B30: 4. Infrastructure and Learning Resources | C30: 4.2 Library as a Learning Resource | D30: QlM | E30: 4.2.1 | F30: Library is automated using Integrated Library Management System (ILMS), subscription to e-resources, amount spent on purchase of books, journals and per day usage of library | G30: 20 | H30: 20 | K30: =IF(J30>80,4,IF(AND(J30<=80,J30>60),3,IF(AND(J30<=60,J30>40),2,IF(AND(J30<=40,J30>20),1,IF(J30<=20,0))))) -> 0 | L30: =K30*G30 -> 0 | M30: =L30 -> 0 | N30: =M30/H30 -> 0
A31: 29 | B31: 4. Infrastructure and Learning Resources | C31: 4.3 IT Infrastructure | D31: QlM | E31: 4.3.1 | F31: Institution frequently updates its IT facilities and provides sufficient bandwidth for internet connection | G31: 20 | H31: 30 | K31: =IF(J31>80,4,IF(AND(J31<=80,J31>60),3,IF(AND(J31<=60,J31>40),2,IF(AND(J31<=40,J31>20),1,IF(J31<=20,0))))) -> 0 | L31: =K31*G31 -> 0 | M31: =L31+L32 -> 20 | N31: =M31/H31 -> 0.66666667
A32: 30 | B32: 4. Infrastructure and Learning Resources | C32: 4.3 IT Infrastructure | D32: QnM | E32: 4.3.2 | F32: Student – Computer ratio (Data for the latest completed academic year) | G32: 10 | J32: 45.38 | K32: =IF(J32>80,4,IF(AND(J32<=80,J32>60),3,IF(AND(J32<=60,J32>40),2,IF(AND(J32<=40,J32>20),1,IF(J32<=20,0))))) -> 2 | L32: =K32*G32 -> 20
A33: 31 | B33: 4. Infrastructure and Learning Resources | C33: 4.4 Maintenance of Campus Infrastructure | D33: QnM | E33: 4.4.1 | F33: Percentage of expenditure incurred on maintenance of infrastructure (physical and academic support facilities) excluding salary component during the last five years(INR in Lakhs) | G33: 20 | H33: 20 | J33: 0.38 | K33: =IF(J33>80,4,IF(AND(J33<=80,J33>60),3,IF(AND(J33<=60,J33>40),2,IF(AND(J33<=40,J33>20),1,IF(J33<=20,0))))) -> 0 | L33: =K33*G33 -> 0 | M33: =L33 -> 0 | N33: =M33/H33 -> 0
A34: 32 | B34: 5. Student Support and Progression | C34: 5.1 Student Support | D34: QnM | E34: 5.1.1 | F34: Percentage of students benefited by scholarships and freeships provided by the Government and Non-Government agencies during last five years | G34: 20 | H34: 50 | I34: 140 | J34: 65.79 | K34: =IF(J34>80,4,IF(AND(J34<=80,J34>60),3,IF(AND(J34<=60,J34>40),2,IF(AND(J34<=40,J34>20),1,IF(J34<=20,0))))) -> 3 | L34: =K34*G34 -> 60 | M34: =SUM(L34:L37) -> 120 | N34: =M34/H34 -> 2.4 | O34: =SUM(M34:M42) -> 245 | P34: =O34/I34 -> 1.75
A35: 33 | B35: 5. Student Support and Progression | C35: 5.1 Student Support | D35: QnM | E35: 5.1.2 | F35: Capacity building and skills enhancement initiatives taken by the institution include the following 1. Soft skills 2. Language and communication skills 3. Life skills (Yoga, physical fitness, health and hygiene) 4. ICT/computing skills | G35: 10 | J35: C | K35: =IF(EXACT(J35,"A"),4,IF(EXACT(J35,"B"),3,IF(EXACT(J35,"C"),2,IF(EXACT(J35,"D"),1,0)))) -> 2 | L35: =K35*G35 -> 20
A36: 34 | B36: 5. Student Support and Progression | C36: 5.1 Student Support | D36: QnM | E36: 5.1.3 | F36: Percentage of students benefitted by guidance for competitive examinations and career counselling offered by the Institution duringthe last five years | G36: 10 | J36: 4.35 | K36: =IF(J36>80,4,IF(AND(J36<=80,J36>60),3,IF(AND(J36<=60,J36>40),2,IF(AND(J36<=40,J36>20),1,IF(J36<=20,0))))) -> 0 | L36: =K36*G36 -> 0
A37: 35 | B37: 5. Student Support and Progression | C37: 5.1 Student Support | D37: QnM | E37: 5.1.4 | F37: The Institution has a transparent mechanism for timely redressal of student grievances including sexual harassment and ragging cases 1. Implementation of guidelines of statutory/regulatory bodies 2. Organisation wide awareness and undertakings on policies with zero tolerance 3. Mechanisms for submission of online/offline students’ grievances 4. Timely redressal of the grievances through appropriate committees | G37: 10 | J37: A | K37: =IF(EXACT(J37,"A"),4,IF(EXACT(J37,"B"),3,IF(EXACT(J37,"C"),2,IF(EXACT(J37,"D"),1,0)))) -> 4 | L37: =K37*G37 -> 40
A38: 36 | B38: 5. Student Support and Progression | C38: 5.2 Student Progression | D38: QnM | E38: 5.2.1 | F38: Percentage of placement of outgoing students and students progressing to higher education during the last five years | G38: 20 | H38: 30 | J38: 74.9 | K38: =IF(J38>80,4,IF(AND(J38<=80,J38>60),3,IF(AND(J38<=60,J38>40),2,IF(AND(J38<=40,J38>20),1,IF(J38<=20,0))))) -> 3 | L38: =K38*G38 -> 60 | M38: =L38+L39 -> 100 | N38: =M38/H38 -> 3.3333333
A39: 37 | B39: 5. Student Support and Progression | C39: 5.2 Student Progression | D39: QnM | E39: 5.2.2 | F39: Average percentage of students qualifying in state/national/international level examinations during the last five years (eg: JAM/CLAT/GATE/ GMAT/CAT/GRE/ TOEFL/ Civil Services/State government examinations) | G39: 10 | J39: 100 | K39: =IF(J39>80,4,IF(AND(J39<=80,J39>60),3,IF(AND(J39<=60,J39>40),2,IF(AND(J39<=40,J39>20),1,IF(J39<=20,0))))) -> 4 | L39: =K39*G39 -> 40
A40: 38 | B40: 5. Student Support and Progression | C40: 5.3 Student Participation and Activities | D40: QnM | E40: 5.3.1 | F40: Number of awards/medals for outstanding performance insports/cultural activities at university/state/national / international level (award for a team event should be counted as one) during the last five years. | G40: 25 | H40: 50 | J40: 11 | K40: =IF(J40>80,4,IF(AND(J40<=80,J40>60),3,IF(AND(J40<=60,J40>40),2,IF(AND(J40<=40,J40>20),1,IF(J40<=20,0))))) -> 0 | L40: =K40*G40 -> 0 | M40: =L40+L41 -> 25 | N40: =M40/H40 -> 0.5
...

Sheet 55(Qn&Ql)m-GS
A1: Grade Sheet
A2: Name of the Institution: | C2: ='Affiliated(55m)'!$J$2 -> Institute Name
A3: Type of the Institution: | C3: ='Affiliated(55m)'!K$1 -> Affiliated
A4: Dates of Visit:
A5: No | B5: Criteria | C5: Weightage (Wi | D5: Criterion-wise weighted Grade Point (CrWGPi) | E5: Criterion- wise Grade Point Averages (CrWGPi/Wi) | G5: Range of Institutional Cumulative Grade Point Average (CGPA) | H5: Letter Grade | I5: Status
A6: 1 | B6: Curricular Aspects | C6: 100 | D6: =SUM('Affiliated(55m)'!M3:M8) -> 80 | E6: =D6/C6 -> 0.8 | G6: 3.51-4.00 | H6: A++ | I6: Accredited
A7: 2 | B7: Teaching-learning and Evaluation | C7: 350 | D7: =SUM('Affiliated(55m)'!M9:M18) -> 585 | E7: =D7/C7 -> 1.6714286 | G7: 3.26-3.500 | H7: A+ | I7: Accredited
A8: 3 | B8: Research, Innovations and Extension | C8: 110 | D8: =SUM('Affiliated(55m)'!M19:M27) -> 115 | E8: =D8/C8 -> 1.0454545 | G8: 3.01-3.25 | H8: A | I8: Accredited
A9: 4 | B9: Infrastructure and Learning Resources | C9: 100 | D9: =SUM('Affiliated(55m)'!M28:M33) -> 60 | E9: =D9/C9 -> 0.6 | G9: 2.76-3.00 | H9: B++ | I9: Accredited
A10: 5 | B10: Student Support and Progression | C10: 140 | D10: =SUM('Affiliated(55m)'!M34:M42) -> 245 | E10: =D10/C10 -> 1.75 | G10: 2.51-2.75 | H10: B+ | I10: Accredited
A11: 6 | B11: Governance, Leadership and Management | C11: 100 | D11: =SUM('Affiliated(55m)'!M43:M51) -> 61 | E11: =D11/C11 -> 0.61 | G11: 2.01-2.50 | H11: B | I11: Accredited
A12: 7 | B12: Institutional Values and Best Practices | C12: 100 | D12: 400 | E12: =D12/C12 -> 4 | G12: 1.51-2.00 | H12: C | I12: Accredited
A13: Total | C13: =SUM(C6:C12) -> 1000 | D13: =SUM(D6:D12) -> 1546 | E13: =D13/C13 -> 1.546 | G13: ≤ 1.50 | H13: D | I13: Not Accredited
A15: =D13/C13 -> 1.546
A17: =IF(AND($A$15<=4,$A$15>=3.51),"A++",IF(AND($A$15<=3.5,$A$15>=3.26),"A+",IF(AND($A$15<=3.25,$A$15>3.01),"A",IF(AND($A$15<=3,$A$15>=2.76),"B++",IF(AND($A$15<=2.75,$A$15>=2.51),"B+",IF(AND($A$15<=2.5,$A$15>=2.01),"B",IF(AND($A$15<=2,$A$15>=1.51),"C","D"))))))) -> C
A19: Criterion wise - Grade Sheet
A20: Name of the Institution: | C20: ='Affiliated(55m)'!$J$2 -> Institute Name
A21: Type of the Institution: | C21: ='Affiliated(55m)'!$K$1 -> Affiliated
A22: Dates of Visit:
A23: No | B23: Criteria and Key Indicators | C23: Key Indicator Weightage (Wi) | D23: Key Indicator Wise Weighted Grade Points (KIWGP)i
A24: Criterion 1: Curricular Aspects
A25: 1.1 | B25: Curriculum Planning and Implementation | C25: 20 | D25: =SUM('Affiliated(55m)'!M3) -> 0
A26: 1.2 | B26: Academic Flexibility | C26: 30 | D26: =SUM('Affiliated(55m)'!M4:M5) -> 0
A27: 1.3 | B27: Curriculum Enrichment | C27: 30 | D27: =SUM('Affiliated(55m)'!M6:M7) -> 0
A28: 1.4 | B28: Feedback System | C28: 20 | D28: =SUM('Affiliated(55m)'!M8) -> 80
A29: Total | C29: =SUM(C25:C28) -> 100 | D29: =SUM(D25:D28) -> 80
D30: Grade | E30: =IF(AND($E$29<=4,$E$29>=3.51),"A++",IF(AND($E$29<=3.5,$E$29>=3.26),"A+",IF(AND($E$29<=3.25,$E$29>3.01),"A",IF(AND($E$29<=3,$E$29>=2.76),"B++",IF(AND($E$29<=2.75,$E$29>=2.51),"B+",IF(AND($E$29<=2.5,$E$29>=2.01),"B",IF(AND($E$29<=2,$E$29>=1.51),"C","D"))))))) -> D
A31: =80/70 -> 1.1428571
A32: Criterion 2: Teaching-learning and Evaluation
A33: 2.1 | B33: Student Enrollment and Profile | C33: 40 | D33: =SUM('Affiliated(55m)'!M9:M10) -> 140
A34: 2.2 | B34: Catering to Student Diversity | C34: 40 | D34: =SUM('Affiliated(55m)'!M11) -> 120
A35: 2.3 | B35: Teaching- Learning Process | C35: 40 | D35: =SUM('Affiliated(55m)'!M12) -> 0
A36: 2.4 | B36: Teacher Profile and Quality | C36: 40 | D36: =SUM('Affiliated(55m)'!M13:M14) -> 85
A37: 2.5 | B37: Evaluation Process and Reforms | C37: 40 | D37: =SUM('Affiliated(55m)'!M15) -> 0
A38: 2.6 | B38: Student Performance and Learning Outcomes | C38: 90 | D38: =SUM('Affiliated(55m)'!M16:M17) -> 180
A39: 2.7 | B39: Student Satisfaction Survey | C39: 60 | D39: =SUM('Affiliated(55m)'!M18) -> 60
A40: Total | C40: =SUM(C33:C39) -> 350 | D40: =SUM(D33:D39) -> 585
A41: =D40/C40 -> 1.6714286
A42: Criterion 3: Research, Innovations and Extension
A43: 3.1 | B43: Resource Mobilization for Research | C43: 10 | D43: =SUM('Affiliated(55m)'!M19) -> 0
...

Sheet 55m-Gradesheet(GS)
A5: No | B5: Criteria | C5: Weightage (Wi | D5: Criterion-wise weighted Grade Point (CrWGPi) | E5: Criterionwise Grade Point Averages (CrWGPi/Wi) | G5: Range of Institutional Cumulative Grade Point Average (CGPA) | H5: Letter Grade | I5: Status
A6: 1 | B6: Curricular Aspects | C6: 100 | D6: =SUM('Affiliated(55m)'!M3:M8) -> 80 | E6: =D6/C6 -> 0.8 | G6: 3.51-4.00 | H6: A++ | I6: Accredited
A7: 2 | B7: Teaching-learning and Evaluation | C7: 350 | D7: =SUM('Affiliated(55m)'!M9:M18) -> 585 | E7: =D7/C7 -> 1.6714286 | G7: 3.26-3.500 | H7: A+ | I7: Accredited
A8: 3 | B8: Research, Innovations and Extension | C8: 110 | D8: =SUM('Affiliated(55m)'!M19:M27) -> 115 | E8: =D8/C8 -> 1.0454545 | G8: 3.01-3.25 | H8: A | I8: Accredited
A9: 4 | B9: Infrastructure and Learning Resources | C9: 100 | D9: =SUM('Affiliated(55m)'!M28:M33) -> 60 | E9: =D9/C9 -> 0.6 | G9: 2.76-3.00 | H9: B++ | I9: Accredited
A10: 5 | B10: Student Support and Progression | C10: 140 | D10: =SUM('Affiliated(55m)'!M34:M42) -> 245 | E10: =D10/C10 -> 1.75 | G10: 2.51-2.75 | H10: B+ | I10: Accredited
A11: 6 | B11: Governance, Leadership and Management | C11: 100 | D11: =SUM('Affiliated(55m)'!M43:M51) -> 61 | E11: =D11/C11 -> 0.61 | G11: 2.01-2.50 | H11: B | I11: Accredited
A12: 7 | B12: Institutional Values and Best Practices | C12: 100 | D12: =SUM('Affiliated(55m)'!M52:M57) -> 100 | E12: =D12/C12 -> 1 | G12: 1.51-2.00 | H12: C | I12: Accredited
C13: =SUM(C6:C12) -> 1000 | D13: =SUM(D6:D12) -> 1246 | E13: =D13/C13 -> 1.246 | G13: ≤ 1.50 | H13: D | I13: Not Accredited
D14: Grade | E14: =IF(AND($E$13<=4,$E$13>=3.51),"A++",IF(AND($E$13<=3.5,$E$13>=3.26),"A+",IF(AND($E$13<=3.25,$E$13>3.01),"A",IF(AND($E$13<=3,$E$13>=2.76),"B++",IF(AND($E$13<=2.75,$E$13>=2.51),"B+",IF(AND($E$13<=2.5,$E$13>=2.01),"B",IF(AND($E$13<=2,$E$13>=1.51),"C","D"))))))) -> D
A16: No | B16: Criteria and Key Indicators | C16: Key Indicator Weightage (Wi) | D16: Key Indicator Wise Weighted Grade Points (KIWGP)i | E16: Key Indicator wise Grade Point Averages (CrWGPi/Wi)
A17: Criterion 1: Curricular Aspects
A18: 1.1 | B18: Curriculum Planning and Implementation | C18: 20 | D18: =SUM('Affiliated(55m)'!L3) -> 0
A19: 1.2 | B19: Academic Flexibility | C19: 30 | D19: =SUM('Affiliated(55m)'!L4:L5) -> 0
A20: 1.3 | B20: 1.3 Curriculum Enrichment | C20: 30 | D20: =SUM('Affiliated(55m)'!L6:L7) -> 0
A21: 1.4 | B21: 1.4 Feedback System | C21: 20 | D21: =SUM('Affiliated(55m)'!L8) -> 80
C22: =SUM(C18:C21) -> 100 | D22: =SUM(D18:D21) -> 80
D23: Grade | E23: *
A24: Criterion 2: Teaching-learning and Evaluation
A25: 2.1 | B25: Student Enrollment and Profile | C25: 40 | D25: =SUM('Affiliated(55m)'!L9:L10) -> 140
A26: 2.2 | B26: Catering to Student Diversity | C26: 40 | D26: =SUM('Affiliated(55m)'!L11) -> 120
A27: 2.3 | B27: Teaching- Learning Process | C27: 40 | D27: =SUM('Affiliated(55m)'!L12) -> 0
A28: 2.4 | B28: Teacher Profile and Quality | C28: 40 | D28: =SUM('Affiliated(55m)'!L13:L14) -> 85
A29: 2.5 | B29: Evaluation Process and Reforms | C29: 40 | D29: =SUM('Affiliated(55m)'!L15) -> 0
A30: 2.6 | B30: Student Performance and Learning Outcomes | C30: 90 | D30: =SUM('Affiliated(55m)'!L16:L17) -> 180
A31: 2.7 | B31: Student Satisfaction Survey | C31: 60 | D31: =SUM('Affiliated(55m)'!L18) -> 60
C32: =SUM(C25:C31) -> 350 | D32: =SUM(D25:D31) -> 585
D33: Grade | E33: =IF(AND($E$32<=4,$E$32>=3.51),"A++",IF(AND($E$32<=3.5,$E$32>=3.26),"A+",IF(AND($E$32<=3.25,$E$32>3.01),"A",IF(AND($E$32<=3,$E$32>=2.76),"B++",IF(AND($E$32<=2.75,$E$32>=2.51),"B+",IF(AND($E$32<=2.5,$E$32>=2.01),"B",IF(AND($E$32<=2,$E$32>=1.51),"C","D"))))))) -> D
A34: Criterion 3: Research, Innovations and Extension
A35: 3.1 | B35: Resource Mobilization for Research | C35: 10 | D35: =SUM('Affiliated(55m)'!L19) -> 0
A36: 3.2 | B36: Innovation Ecosystem | C36: 15 | D36: =SUM('Affiliated(55m)'!L20:L21) -> 5
A37: 3.3 | B37: Research Publications and Awards | C37: 25 | D37: =SUM('Affiliated(55m)'!L22:L23) -> 30
A38: 3.4 | B38: Extension Activities | C38: 40 | D38: =SUM('Affiliated(55m)'!L24:L26) -> 80
A39: 3.5 | B39: Collaboration | C39: 20 | D39: =SUM('Affiliated(55m)'!L27) -> 0
C40: =SUM(C35:C39) -> 110 | D40: =SUM(D35:D39) -> 115
D41: Grade | E41: =IF(AND($E$47<=4,$E$47>=3.51),"A++",IF(AND($E$47<=3.5,$E$47>=3.26),"A+",IF(AND($E$47<=3.25,$E$47>3.01),"A",IF(AND($E$47<=3,$E$47>=2.76),"B++",IF(AND($E$47<=2.75,$E$47>=2.51),"B+",IF(AND($E$47<=2.5,$E$47>=2.01),"B",IF(AND($E$47<=2,$E$47>=1.51),"C","D"))))))) -> D
A42: Criterion 4: Infrastructure and Learning Resources
A43: 4.1 | B43: Physical Facilities | C43: 30 | D43: =SUM('Affiliated(55m)'!L28:L29) -> 40
A44: 4.2 | B44: Library as a Learning Resource | C44: 20 | D44: =SUM('Affiliated(55m)'!L30) -> 0
A45: 4.3 | B45: IT Infrastructure | C45: 30 | D45: =SUM('Affiliated(55m)'!L31:L32) -> 20
...

Sheet Qn (34m)
A2: S. No | B2: Criteria © | C2: Key Indicator (KI) | D2: Metric (M) Type | E2: Metric (M) Num | F2: Metric (M) Description | G2: M Wt | H2: KI Wt | I2: © Wt | J2: Response | K2: Metric Grade scale (0-4) | L2: M wise weighted Grade points | M2: KIwise weighted Grade points | N2: KIwise weighted Grade points Average | O2: ©Wise Weighted Average | P2: ©Wise Weighted Grade Point Average
A3: =SUBTOTAL(3,$B$3:B3) -> 1 | B3: 1. Curricular Aspects | C3: 1.2 Academic Flexibility | D3: QnM | E3: 1.2.1 | F3: Number of Add on /Certificate/ Value added programs offered during the last five years | G3: 15 | H3: 30 | I3: 70 | J3: =VLOOKUP(E3,'Affiliated(55m)'!$E$3:$J$57,6,0) -> 4 | K3: =IF(J3>80,4,IF(AND(J3<=80,J3>60),3,IF(AND(J3<=60,J3>40),2,IF(AND(J3<=40,J3>20),1,IF(J3<=20,0))))) -> 0 | L3: =K3*G3 -> 0 | M3: =SUM(L3:L4) -> 0 | N3: =M3/H3 -> 0 | O3: =SUM(M3:M6) -> 80 | P3: =O3/I3 -> 1.1428571
A4: =SUBTOTAL(3,$B$3:B4) -> 2 | B4: 1. Curricular Aspects | C4: 1.2 Academic Flexibility | D4: QnM | E4: 1.2.2 | F4: Average percentage of students enrolled in Certificate/ Add-on/ Value added programs as against the total number of students during the last five years | G4: 15 | J4: =VLOOKUP(E4,'Affiliated(55m)'!$E$3:$J$57,6,0) -> 1.29 | K4: =IF(J4>80,4,IF(AND(J4<=80,J4>60),3,IF(AND(J4<=60,J4>40),2,IF(AND(J4<=40,J4>20),1,IF(J4<=20,0))))) -> 0 | L4: =K4*G4 -> 0
A5: =SUBTOTAL(3,$B$3:B5) -> 3 | B5: 1. Curricular Aspects | C5: 1.3 Curriculum Enrichment | D5: QnM | E5: 1.3.2 | F5: Percentage of students undertaking project work/field work/internships (Data for the latest completed academic year) | G5: 20 | H5: 20 | J5: =VLOOKUP(E5,'Affiliated(55m)'!$E$3:$J$57,6,0) -> 17.77 | K5: =IF(J5>80,4,IF(AND(J5<=80,J5>60),3,IF(AND(J5<=60,J5>40),2,IF(AND(J5<=40,J5>20),1,IF(J5<=20,0))))) -> 0 | L5: =K5*G5 -> 0 | M5: =L5 -> 0 | N5: =M5/H5 -> 0
A6: =SUBTOTAL(3,$B$3:B6) -> 4 | B6: 1. Curricular Aspects | C6: 1.4 Feedback System | D6: QnM | E6: 1.4.1 | F6: Institution obtains feedback on the academic performance and ambience of the institution from various stakeholders, such as Students, Teachers, Employers, Alumni etc. and action taken report on the feedback is made available on institutional website (Yes or No) | G6: 20 | H6: 20 | J6: =VLOOKUP(E6,'Affiliated(55m)'!$E$3:$J$57,6,0) -> Yes | K6: =IF(EXACT(J6,"Yes"),4) -> 4 | L6: =K6*G6 -> 80 | M6: =L6 -> 80 | N6: =M6/H6 -> 4
A7: =SUBTOTAL(3,$B$3:B7) -> 5 | B7: 2. Teaching-Learning and Evaluation | C7: 2.1 Student Enrolment and Profile | D7: QnM | E7: 2.1.1 | F7: Enrolment percentage | G7: 20 | H7: 40 | I7: 225 | J7: =VLOOKUP(E7,'Affiliated(55m)'!$E$3:$J$57,6,0) -> 68.39 | K7: =IF(J7>80,4,IF(AND(J7<=80,J7>60),3,IF(AND(J7<=60,J7>40),2,IF(AND(J7<=40,J7>20),1,IF(J7<=20,0))))) -> 3 | L7: =K7*G7 -> 60 | M7: =SUM(L7:L8) -> 140 | N7: =M7/H7 -> 3.5 | O7: =SUM(M7:M13) -> 585 | P7: =O7/I7 -> 2.6
A8: =SUBTOTAL(3,$B$3:B8) -> 6 | B8: 2. Teaching-Learning and Evaluation | C8: 2.1 Student Enrolment and Profile | D8: QnM | E8: 2.1.2 | F8: Percentage of seats filled against seats reserved for various categories (SC, ST, OBC, Divyangjan, etc. as per applicable reservation policy during the last five years ( exclusive of supernumerary seats) | G8: 20 | J8: =VLOOKUP(E8,'Affiliated(55m)'!$E$3:$J$57,6,0) -> 96.16 | K8: =IF(J8>80,4,IF(AND(J8<=80,J8>60),3,IF(AND(J8<=60,J8>40),2,IF(AND(J8<=40,J8>20),1,IF(J8<=20,0))))) -> 4 | L8: =K8*G8 -> 80
A9: =SUBTOTAL(3,$B$3:B9) -> 7 | B9: 2. Teaching-Learning and Evaluation | C9: 2.2 Student Teacher Ratio | D9: QnM | E9: 2.2.1 | F9: Student- Full time teacher ratio (Data for the latest completed academic year) | G9: 40 | H9: 40 | J9: =VLOOKUP(E9,'Affiliated(55m)'!$E$3:$J$57,6,0) -> 60.5 | K9: =IF(J9>80,4,IF(AND(J9<=80,J9>60),3,IF(AND(J9<=60,J9>40),2,IF(AND(J9<=40,J9>20),1,IF(J9<=20,0))))) -> 3 | L9: =K9*G9 -> 120 | M9: =L9 -> 120 | N9: =M9/H9 -> 3
A10: =SUBTOTAL(3,$B$3:B10) -> 8 | B10: 2. Teaching-Learning and Evaluation | C10: 2.4 Teacher Profile and Quality | D10: QnM | E10: 2.4.1 | F10: Percentage of full time teachers against sanctioned posts during the last five years | G10: 15 | H10: 40 | J10: =VLOOKUP(E10,'Affiliated(55m)'!$E$3:$J$57,6,0) -> 100 | K10: =IF(J10>80,4,IF(AND(J10<=80,J10>60),3,IF(AND(J10<=60,J10>40),2,IF(AND(J10<=40,J10>20),1,IF(J10<=20,0))))) -> 4 | L10: =K10*G10 -> 60 | M10: =SUM(L10:L11) -> 85 | N10: =M10/H10 -> 2.125
A11: =SUBTOTAL(3,$B$3:B11) -> 9 | B11: 2. Teaching-Learning and Evaluation | C11: 2.4 Teacher Profile and Quality | D11: QnM | E11: 2.4.2 | F11: Percentage of full time teachers with NET/SET/SLET/ Ph. D. / D.M. / M.Ch. / D.N.B Super speciality / D.Sc. / D.Litt. during the last five years (consider only highest degree for count) | G11: 25 | J11: =VLOOKUP(E11,'Affiliated(55m)'!$E$3:$J$57,6,0) -> 23.85 | K11: =IF(J11>80,4,IF(AND(J11<=80,J11>60),3,IF(AND(J11<=60,J11>40),2,IF(AND(J11<=40,J11>20),1,IF(J11<=20,0))))) -> 1 | L11: =K11*G11 -> 25
A12: =SUBTOTAL(3,$B$3:B12) -> 10 | B12: 2. Teaching-Learning and Evaluation | C12: 2.6 Student Performance and Learning Outcomes | D12: QnM | E12: 2.6.2 | F12: Pass percentage of Students during last five years | G12: 45 | H12: 45 | J12: =VLOOKUP(E12,'Affiliated(55m)'!$E$3:$J$57,6,0) -> 98.36 | K12: =IF(J12>80,4,IF(AND(J12<=80,J12>60),3,IF(AND(J12<=60,J12>40),2,IF(AND(J12<=40,J12>20),1,IF(J12<=20,0))))) -> 4 | L12: =K12*G12 -> 180 | M12: =L12 -> 180 | N12: =M12/H12 -> 4
A13: =SUBTOTAL(3,$B$3:B13) -> 11 | B13: 2. Teaching-Learning and Evaluation | C13: 2.7 Student Satisfaction Survey | D13: QnM | E13: 2.7.1 | F13: Online student satisfaction survey regarding to teaching learning process. (Online survey to be conducted) | G13: 60 | H13: 60 | J13: =VLOOKUP(E13,'Affiliated(55m)'!$E$3:$J$57,6,0) -> 29 | K13: =IF(J13>80,4,IF(AND(J13<=80,J13>60),3,IF(AND(J13<=60,J13>40),2,IF(AND(J13<=40,J13>20),1,IF(J13<=20,0))))) -> 1 | L13: =K13*G13 -> 60 | M13: =L13 -> 60 | N13: =M13/H13 -> 1
A14: =SUBTOTAL(3,$B$3:B14) -> 12 | B14: 3. Research, Innovations and Extension | C14: 3.1 Resource Mobilization for Research | D14: QnM | E14: 3.1.1 | F14: Grants received from Government and non-governmental agencies for research projects, endowments, Chairs in the institution during the last five years (INR in Lakhs) | G14: 10 | H14: 10 | I14: 80 | J14: =VLOOKUP(E14,'Affiliated(55m)'!$E$3:$J$57,6,0) -> 0 | K14: =IF(J14>80,4,IF(AND(J14<=80,J14>60),3,IF(AND(J14<=60,J14>40),2,IF(AND(J14<=40,J14>20),1,IF(J14<=20,0))))) -> 0 | L14: =K14*G14 -> 0 | M14: =L14 -> 0 | N14: =M14/H14 -> 0 | O14: =SUM(M14:M19) -> 115 | P14: =O14/I14 -> 1.4375
A15: =SUBTOTAL(3,$B$3:B15) -> 13 | B15: 3. Research, Innovations and Extension | C15: 3.2 Innovation Ecosystem | D15: QnM | E15: 3.2.2 | F15: Number of workshops/seminars conducted on Research Methodology, Intellectual Property Rights (IPR) and entrepreneurship during the last five years | G15: 5 | H15: 5 | J15: =VLOOKUP(E15,'Affiliated(55m)'!$E$3:$J$57,6,0) -> 26 | K15: =IF(J15>80,4,IF(AND(J15<=80,J15>60),3,IF(AND(J15<=60,J15>40),2,IF(AND(J15<=40,J15>20),1,IF(J15<=20,0))))) -> 1 | L15: =K15*G15 -> 5 | M15: =L15 -> 5 | N15: =M15/H15 -> 1
A16: =SUBTOTAL(3,$B$3:B16) -> 14 | B16: 3. Research, Innovations and Extension | C16: 3.3 Research Publications and Awards | D16: QnM | E16: 3.3.1 | F16: Number of research papers per teachers in the Journals notified on UGC website during the last five years | G16: 10 | H16: 25 | J16: =VLOOKUP(E16,'Affiliated(55m)'!$E$3:$J$57,6,0) -> 11.54 | K16: =IF(J16>80,4,IF(AND(J16<=80,J16>60),3,IF(AND(J16<=60,J16>40),2,IF(AND(J16<=40,J16>20),1,IF(J16<=20,0))))) -> 0 | L16: =K16*G16 -> 0 | M16: =SUM(L16:L17) -> 30 | N16: =M16/H16 -> 1.2
A17: =SUBTOTAL(3,$B$3:B17) -> 15 | B17: 3. Research, Innovations and Extension | C17: 3.3 Research Publications and Awards | D17: QnM | E17: 3.3.2 | F17: Number of books and chapters in edited volumes/books published and papers published in national/ international conference proceedings per teacher during last five years | G17: 15 | J17: =VLOOKUP(E17,'Affiliated(55m)'!$E$3:$J$57,6,0) -> 53.85 | K17: =IF(J17>80,4,IF(AND(J17<=80,J17>60),3,IF(AND(J17<=60,J17>40),2,IF(AND(J17<=40,J17>20),1,IF(J17<=20,0))))) -> 2 | L17: =K17*G17 -> 30
A18: =SUBTOTAL(3,$B$3:B18) -> 16 | B18: 3. Research, Innovations and Extension | C18: 3.4 Extension Activities | D18: QnM | E18: 3.4.3 | F18: Number of extension and outreach Programmes conducted by the institution through NSS/ NCC/ Red Cross/ YRC etc., (including the programmes such as Swachh Bharat, AIDS awareness, Gender issues etc. )and/or those organised in collaboration with industry, community and NGOs during the last five years | G18: 20 | H18: 20 | J18: =VLOOKUP(E18,'Affiliated(55m)'!$E$3:$J$57,6,0) -> 90 | K18: =IF(J18>80,4,IF(AND(J18<=80,J18>60),3,IF(AND(J18<=60,J18>40),2,IF(AND(J18<=40,J18>20),1,IF(J18<=20,0))))) -> 4 | L18: =K18*G18 -> 80 | M18: =L18 -> 80 | N18: =M18/H18 -> 4
A19: =SUBTOTAL(3,$B$3:B19) -> 17 | B19: 3. Research, Innovations and Extension | C19: 3.5 Collaboration | D19: QnM | E19: 3.5.1 | F19: The number of MoUs, collaborations/linkages for Faculty exchange, Student exchange, Internship, Field trip, On-the- job training, research and other academic activities during the last five years | G19: 20 | H19: 20 | J19: =VLOOKUP(E19,'Affiliated(55m)'!$E$3:$J$57,6,0) -> 1 | K19: =IF(J19>80,4,IF(AND(J19<=80,J19>60),3,IF(AND(J19<=60,J19>40),2,IF(AND(J19<=40,J19>20),1,IF(J19<=20,0))))) -> 0 | L19: =K19*G19 -> 0 | M19: =L19 -> 0 | N19: =M19/H19 -> 0
A20: =SUBTOTAL(3,$B$3:B20) -> 18 | B20: 4. Infrastructure and Learning Resources | C20: 4.1 Physical Facilities | D20: QnM | E20: 4.1.2 | F20: Percentage of expenditure, excluding salary for infrastructure augmentation during last five years(INR in Lakhs) | G20: 10 | H20: 10 | I20: 40 | J20: =VLOOKUP(E20,'Affiliated(55m)'!$E$3:$J$57,6,0) -> 100 | K20: =IF(J20>80,4,IF(AND(J20<=80,J20>60),3,IF(AND(J20<=60,J20>40),2,IF(AND(J20<=40,J20>20),1,IF(J20<=20,0))))) -> 4 | L20: =K20*G20 -> 40 | M20: =L20 -> 40 | N20: =M20/H20 -> 4 | O20: =SUM(M20:M22) -> 60 | P20: =O20/I20 -> 1.5
A21: =SUBTOTAL(3,$B$3:B21) -> 19 | B21: 4. Infrastructure and Learning Resources | C21: 4.3 IT Infrastructure | D21: QnM | E21: 4.3.2 | F21: Student – Computer ratio (Data for the latest completed academic year) | G21: 10 | H21: 10 | J21: =VLOOKUP(E21,'Affiliated(55m)'!$E$3:$J$57,6,0) -> 45.38 | K21: =IF(J21>80,4,IF(AND(J21<=80,J21>60),3,IF(AND(J21<=60,J21>40),2,IF(AND(J21<=40,J21>20),1,IF(J21<=20,0))))) -> 2 | L21: =K21*G21 -> 20 | M21: =L21 -> 20 | N21: =M21/H21 -> 2
A22: =SUBTOTAL(3,$B$3:B22) -> 20 | B22: 4. Infrastructure and Learning Resources | C22: 4.4 Maintenance of Campus Infrastructure | D22: QnM | E22: 4.4.1 | F22: Percentage of expenditure incurred on maintenance of infrastructure (physical and academic support facilities) excluding salary component during the last five years(INR in Lakhs) | G22: 20 | H22: 20 | J22: =VLOOKUP(E22,'Affiliated(55m)'!$E$3:$J$57,6,0) -> 0.38 | K22: =IF(J22>80,4,IF(AND(J22<=80,J22>60),3,IF(AND(J22<=60,J22>40),2,IF(AND(J22<=40,J22>20),1,IF(J22<=20,0))))) -> 0 | L22: =K22*G22 -> 0 | M22: =L22 -> 0 | N22: =M22/H22 -> 0
A23: =SUBTOTAL(3,$B$3:B23) -> 21 | B23: 5. Student Support and Progression | C23: 5.1 Student Support | D23: QnM | E23: 5.1.1 | F23: Percentage of students benefited by scholarships and freeships provided by the Government and Non-Government agencies during last five years | G23: 20 | H23: 50 | I23: 130 | J23: =VLOOKUP(E23,'Affiliated(55m)'!$E$3:$J$57,6,0) -> 65.79 | K23: =IF(J23>80,4,IF(AND(J23<=80,J23>60),3,IF(AND(J23<=60,J23>40),2,IF(AND(J23<=40,J23>20),1,IF(J23<=20,0))))) -> 3 | L23: =K23*G23 -> 60 | M23: =SUM(L23:L26) -> 120 | N23: =M23/H23 -> 2.4 | O23: =SUM(M23:M30) -> 245 | P23: =O23/I23 -> 1.8846154
A24: =SUBTOTAL(3,$B$3:B24) -> 22 | B24: 5. Student Support and Progression | C24: 5.1 Student Support | D24: QnM | E24: 5.1.2 | F24: Capacity building and skills enhancement initiatives taken by the institution include the following 1. Soft skills 2. Language and communication skills 3. Life skills (Yoga, physical fitness, health and hygiene) 4. ICT/computing skills | G24: 10 | J24: =VLOOKUP(E24,'Affiliated(55m)'!$E$3:$J$57,6,0) -> C | K24: =IF(EXACT(J24,"A"),4,IF(EXACT(J24,"B"),3,IF(EXACT(J24,"C"),2,IF(EXACT(J24,"D"),1,0)))) -> 2 | L24: =K24*G24 -> 20
A25: =SUBTOTAL(3,$B$3:B25) -> 23 | B25: 5. Student Support and Progression | C25: 5.1 Student Support | D25: QnM | E25: 5.1.3 | F25: Percentage of students benefitted by guidance for competitive examinations and career counselling offered by the Institution duringthe last five years | G25: 10 | J25: =VLOOKUP(E25,'Affiliated(55m)'!$E$3:$J$57,6,0) -> 4.35 | K25: =IF(J25>80,4,IF(AND(J25<=80,J25>60),3,IF(AND(J25<=60,J25>40),2,IF(AND(J25<=40,J25>20),1,IF(J25<=20,0))))) -> 0 | L25: =K25*G25 -> 0
A26: =SUBTOTAL(3,$B$3:B26) -> 24 | B26: 5. Student Support and Progression | C26: 5.1 Student Support | D26: QnM | E26: 5.1.4 | F26: The Institution has a transparent mechanism for timely redressal of student grievances including sexual harassment and ragging cases 1. Implementation of guidelines of statutory/regulatory bodies 2. Organisation wide awareness and undertakings on policies with zero tolerance 3. Mechanisms for submission of online/offline students’ grievances 4. Timely redressal of the grievances through appropriate committees | G26: 10 | J26: =VLOOKUP(E26,'Affiliated(55m)'!$E$3:$J$57,6,0) -> A | K26: =IF(EXACT(J26,"A"),4,IF(EXACT(J26,"B"),3,IF(EXACT(J26,"C"),2,IF(EXACT(J26,"D"),1,0)))) -> 4 | L26: =K26*G26 -> 40
A27: =SUBTOTAL(3,$B$3:B27) -> 25 | B27: 5. Student Support and Progression | C27: 5.2 Student Progression | D27: QnM | E27: 5.2.1 | F27: Percentage of placement of outgoing students and students progressing to higher education during the last five years | G27: 20 | H27: 30 | J27: =VLOOKUP(E27,'Affiliated(55m)'!$E$3:$J$57,6,0) -> 74.9 | K27: =IF(J27>80,4,IF(AND(J27<=80,J27>60),3,IF(AND(J27<=60,J27>40),2,IF(AND(J27<=40,J27>20),1,IF(J27<=20,0))))) -> 3 | L27: =K27*G27 -> 60 | M27: =SUM(L27:L28) -> 100 | N27: =M27/H27 -> 3.3333333
A28: =SUBTOTAL(3,$B$3:B28) -> 26 | B28: 5. Student Support and Progression | C28: 5.2 Student Progression | D28: QnM | E28: 5.2.2 | F28: Average percentage of students qualifying in state/national/international level examinations during the last five years (eg: JAM/CLAT/GATE/ GMAT/CAT/GRE/ TOEFL/ Civil Services/State government examinations) | G28: 10 | J28: =VLOOKUP(E28,'Affiliated(55m)'!$E$3:$J$57,6,0) -> 100 | K28: =IF(J28>80,4,IF(AND(J28<=80,J28>60),3,IF(AND(J28<=60,J28>40),2,IF(AND(J28<=40,J28>20),1,IF(J28<=20,0))))) -> 4 | L28: =K28*G28 -> 40
A29: =SUBTOTAL(3,$B$3:B29) -> 27 | B29: 5. Student Support and Progression | C29: 5.3 Student Participation and Activities | D29: QnM | E29: 5.3.1 | F29: Number of awards/medals for outstanding performance insports/cultural activities at university/state/national / international level (award for a team event should be counted as one) during the last five years. | G29: 25 | H29: 50 | J29: =VLOOKUP(E29,'Affiliated(55m)'!$E$3:$J$57,6,0) -> 11 | K29: =IF(J29>80,4,IF(AND(J29<=80,J29>60),3,IF(AND(J29<=60,J29>40),2,IF(AND(J29<=40,J29>20),1,IF(J29<=20,0))))) -> 0 | L29: =K29*G29 -> 0 | M29: =SUM(L29:L30) -> 25 | N29: =M29/H29 -> 0.5
A30: =SUBTOTAL(3,$B$3:B30) -> 28 | B30: 5. Student Support and Progression | C30: 5.3 Student Participation and Activities | D30: QnM | E30: 5.3.2 | F30: Average number of sports and cultural events/competitions in which students of the Institution participated during last five years(organised by the institution/other institutions) | G30: 25 | J30: =VLOOKUP(E30,'Affiliated(55m)'!$E$3:$J$57,6,0) -> 22.4 | K30: =IF(J30>80,4,IF(AND(J30<=80,J30>60),3,IF(AND(J30<=60,J30>40),2,IF(AND(J30<=40,J30>20),1,IF(J30<=20,0))))) -> 1 | L30: =K30*G30 -> 25
A31: =SUBTOTAL(3,$B$3:B31) -> 29 | B31: 6. Governance, Leadership and Management | C31: 6.2 Strategy Development and Deployment | D31: QnM | E31: 6.2.2 | F31: Implementation of e-governance in areas of operation 1. Administration 2. Finance and Accounts 3. Student Admission and Support 4. Examination | G31: 4 | H31: 4 | I31: 46 | J31: =VLOOKUP(E31,'Affiliated(55m)'!$E$3:$J$57,6,0) -> A | K31: =IF(EXACT(J31,"A"),4,IF(EXACT(J31,"B"),3,IF(EXACT(J31,"C"),2,IF(EXACT(J31,"D"),1,0)))) -> 4 | L31: =K31*G31 -> 16 | M31: =L31 -> 16 | N31: =M31/H31 -> 4 | O31: =SUM(M31:M34) -> 61 | P31: =O31/I31 -> 1.326087
A32: =SUBTOTAL(3,$B$3:B32) -> 30 | B32: 6. Governance, Leadership and Management | C32: 6.3 Faculty Empowerment Strategies | D32: QnM | E32: 6.3.2 | F32: Percentage of teachers provided with financial support to attend conferences/workshops and towards membership fee of professional bodies during the last five years | G32: 12 | H32: 27 | J32: =VLOOKUP(E32,'Affiliated(55m)'!$E$3:$J$57,6,0) -> 0 | K32: =IF(J32>80,4,IF(AND(J32<=80,J32>60),3,IF(AND(J32<=60,J32>40),2,IF(AND(J32<=40,J32>20),1,IF(J32<=20,0))))) -> 0 | L32: =K32*G32 -> 0 | M32: =SUM(L32:L33) -> 0 | N32: =M32/H32 -> 0
A33: =SUBTOTAL(3,$B$3:B33) -> 31 | B33: 6. Governance, Leadership and Management | C33: 6.3 Faculty Empowerment Strategies | D33: QnM | E33: 6.3.3 | F33: Percentage of teaching and non-teaching staff participating in Faculty development Programmes (FDP), professional development /administrative training programs during the last five years | G33: 15 | J33: =VLOOKUP(E33,'Affiliated(55m)'!$E$3:$J$57,6,0) -> 5.52 | K33: =IF(J33>80,4,IF(AND(J33<=80,J33>60),3,IF(AND(J33<=60,J33>40),2,IF(AND(J33<=40,J33>20),1,IF(J33<=20,0))))) -> 0 | L33: =K33*G33 -> 0
A34: =SUBTOTAL(3,$B$3:B34) -> 32 | B34: 6. Governance, Leadership and Management | C34: 6.5 Internal Quality Assurance System (IQAS) | D34: QnM | E34: 6.5.2 | F34: Quality assurance initiatives of the institution include: 1. Regular meeting of Internal Quality Assurance Cell (IQAC); Feedback collected, analysed and used for improvements 2. Collaborative quality initiatives with other institution(s)/ membership of international networks 3. Participation in NIRF 4. any other quality audit/accreditation recognized by state, national or international agencies such as NAAC, NBA, ISO Certification etc | G34: 15 | H34: 15 | J34: =VLOOKUP(E34,'Affiliated(55m)'!$E$3:$J$57,6,0) -> B | K34: =IF(EXACT(J34,"A"),4,IF(EXACT(J34,"B"),3,IF(EXACT(J34,"C"),2,IF(EXACT(J34,"D"),1,0)))) -> 3 | L34: =K34*G34 -> 45 | M34: =L34 -> 45 | N34: =M34/H34 -> 3
A35: =SUBTOTAL(3,$B$3:B35) -> 33 | B35: 7. Institutional Values and Best Practices | C35: 7.1 Institutional Values and Social Responsibilities | D35: QnM | E35: 7.1.2 | F35: The Institution has facilities and initiatives for 1. Alternate sources of energy and energy conservation measures 2. Management of the various types of degradable and non-degradable waste 3. Water conservation 4. Green campus initiatives 5. Disabled-friendly, barrier free environment | G35: 20 | H35: 30 | I35: 30 | J35: =VLOOKUP(E35,'Affiliated(55m)'!$E$3:$J$57,6,0) -> A | K35: =IF(EXACT(J35,"A"),4,IF(EXACT(J35,"B"),3,IF(EXACT(J35,"C"),2,IF(EXACT(J35,"D"),1,0)))) -> 4 | L35: =K35*G35 -> 80 | M35: =SUM(L35:L36) -> 100 | N35: =M35/H35 -> 3.3333333 | O35: =SUM(M35:M36) -> 100 | P35: =O35/I35 -> 3.3333333
A36: =SUBTOTAL(3,$B$3:B36) -> 34 | B36: 7. Institutional Values and Best Practices | C36: 7.1 Institutional Values and Social Responsibilities | D36: QnM | E36: 7.1.3 | F36: Quality audits on environment and energy regularly undertaken by the Institution. The institutional environment and energy initiatives are confirmed through the following 1. Green audit / Environment audit 2. Energy audit 3. Clean and green campus initiatives 4. Beyond the campus environmental promotion activities | G36: 10 | J36: =VLOOKUP(E36,'Affiliated(55m)'!$E$3:$J$57,6,0) -> C | K36: =IF(EXACT(J36,"A"),4,IF(EXACT(J36,"B"),3,IF(EXACT(J36,"C"),2,IF(EXACT(J36,"D"),1,0)))) -> 2 | L36: =K36*G36 -> 20
J39: Graphical Representation of Grade points
F42: Row Labels | G42: Average of Metric | J42: Criteria Wise QnM Grade Points(0-4)
F43: 1. Curricular Aspects | G43: 1
F44: 2. Teaching-Learning and Evaluation | G44: 2.1428571
F45: 3. Research, Innovations and Extension | G45: 1
...

Sheet 34
A1: Grade Sheet
A2: Name of the Institution: | C2: ='Affiliated(55m)'!$J$2 -> Institute Name
A3: Type of the Institution: | C3: ='Affiliated(55m)'!K$1 -> Affiliated
A4: Dates of Visit:
A5: No | B5: Criteria | C5: Weightage (Wi | D5: Criterion-wise weighted Grade Point (CrWGPi) | E5: Criterion- wise Grade Point Averages (CrWGPi/Wi) | G5: Range of Institutional Cumulative Grade Point Average (CGPA) | H5: Letter Grade | I5: Status
A6: 1 | B6: Curricular Aspects | C6: 70 | D6: =SUM('Qn (34m)'!O3:O6) -> 80 | E6: =D6/C6 -> 1.1428571 | G6: 3.51-4.00 | H6: A++ | I6: Accredited
A7: 2 | B7: Teaching-learning and Evaluation | C7: 225 | D7: =SUM('Qn (34m)'!O7:O13) -> 585 | E7: =D7/C7 -> 2.6 | G7: 3.26-3.500 | H7: A+ | I7: Accredited
A8: 3 | B8: Research, Innovations and Extension | C8: 80 | D8: =SUM('Qn (34m)'!O14:O19) -> 115 | E8: =D8/C8 -> 1.4375 | G8: 3.01-3.25 | H8: A | I8: Accredited
A9: 4 | B9: Infrastructure and Learning Resources | C9: 40 | D9: =SUM('Qn (34m)'!O20:O22) -> 60 | E9: =D9/C9 -> 1.5 | G9: 2.76-3.00 | H9: B++ | I9: Accredited
A10: 5 | B10: Student Support and Progression | C10: 130 | D10: =SUM('Qn (34m)'!O23:O30) -> 245 | E10: =D10/C10 -> 1.8846154 | G10: 2.51-2.75 | H10: B+ | I10: Accredited
A11: 6 | B11: Governance, Leadership and Management | C11: 46 | D11: =SUM('Qn (34m)'!O31:O34) -> 61 | E11: =D11/C11 -> 1.326087 | G11: 2.01-2.50 | H11: B | I11: Accredited
A12: 7 | B12: Institutional Values and Best Practices | C12: 30 | D12: =SUM('Qn (34m)'!O35:O36) -> 100 | E12: =D12/C12 -> 3.3333333 | G12: 1.51-2.00 | H12: C | I12: Accredited
A13: Total | C13: =SUM(C6:C12) -> 621 | D13: =SUM(D6:D12) -> 1246 | E13: =D13/C13 -> 2.0064412 | G13: ≤ 1.50 | H13: D | I13: Not Accredited
A15: =D13/C13 -> 2.0064412
A17: =IF(AND($A$15<=4,$A$15>=3.51),"A++",IF(AND($A$15<=3.5,$A$15>=3.26),"A+",IF(AND($A$15<=3.25,$A$15>3.01),"A",IF(AND($A$15<=3,$A$15>=2.76),"B++",IF(AND($A$15<=2.75,$A$15>=2.51),"B+",IF(AND($A$15<=2.5,$A$15>=2.01),"B",IF(AND($A$15<=2,$A$15>=1.51),"C","D"))))))) -> D
A19: Criterion wise - Grade Sheet
A20: Name of the Institution: | C20: ='Affiliated(55m)'!$J$2 -> Institute Name
A21: Type of the Institution: | C21: ='Affiliated(55m)'!$K$1 -> Affiliated
A22: Dates of Visit:
A23: No | B23: Criteria and Key Indicators | C23: Key Indicator Weightage (Wi) | D23: Key Indicator Wise Weighted Grade Points (KIWGP)i
A24: Criterion 1: Curricular Aspects
A25: 1.1 | B25: Curriculum Planning and Implementation | C25: 20 | D25: =SUM('Affiliated(55m)'!M3) -> 0
A26: 1.2 | B26: Academic Flexibility | C26: 30 | D26: =SUM('Affiliated(55m)'!M4:M5) -> 0
A27: 1.3 | B27: Curriculum Enrichment | C27: 30 | D27: =SUM('Affiliated(55m)'!M6:M7) -> 0
A28: 1.4 | B28: Feedback System | C28: 20 | D28: =SUM('Affiliated(55m)'!M8) -> 80
A29: Total | C29: =SUM(C25:C28) -> 100 | D29: =SUM(D25:D28) -> 80
D30: Grade | E30: =IF(AND($E$29<=4,$E$29>=3.51),"A++",IF(AND($E$29<=3.5,$E$29>=3.26),"A+",IF(AND($E$29<=3.25,$E$29>3.01),"A",IF(AND($E$29<=3,$E$29>=2.76),"B++",IF(AND($E$29<=2.75,$E$29>=2.51),"B+",IF(AND($E$29<=2.5,$E$29>=2.01),"B",IF(AND($E$29<=2,$E$29>=1.51),"C","D"))))))) -> D
A31: =80/70 -> 1.1428571
A32: Criterion 2: Teaching-learning and Evaluation
A33: 2.1 | B33: Student Enrollment and Profile | C33: 40 | D33: =SUM('Affiliated(55m)'!M9:M10) -> 140
A34: 2.2 | B34: Catering to Student Diversity | C34: 40 | D34: =SUM('Affiliated(55m)'!M11) -> 120
A35: 2.3 | B35: Teaching- Learning Process | C35: 40 | D35: =SUM('Affiliated(55m)'!M12) -> 0
A36: 2.4 | B36: Teacher Profile and Quality | C36: 40 | D36: =SUM('Affiliated(55m)'!M13:M14) -> 85
A37: 2.5 | B37: Evaluation Process and Reforms | C37: 40 | D37: =SUM('Affiliated(55m)'!M15) -> 0
A38: 2.6 | B38: Student Performance and Learning Outcomes | C38: 90 | D38: =SUM('Affiliated(55m)'!M16:M17) -> 180
A39: 2.7 | B39: Student Satisfaction Survey | C39: 60 | D39: =SUM('Affiliated(55m)'!M18) -> 60
A40: Total | C40: =SUM(C33:C39) -> 350 | D40: =SUM(D33:D39) -> 585
A41: =D40/C40 -> 1.6714286
A42: Criterion 3: Research, Innovations and Extension
A43: 3.1 | B43: Resource Mobilization for Research | C43: 10 | D43: =SUM('Affiliated(55m)'!M19) -> 0
...

Sheet 34 Qnm-GS
A1: Quantitative Grade Sheet
A2: Name of the Institution: | C2: ='Affiliated(55m)'!$J$2 -> Institute Name
A3: Type of the Institution: | C3: ='Affiliated(55m)'!K$1 -> Affiliated
A4: Dates of Visit:
A5: No | B5: Criteria | C5: Weightage (Wi | D5: Criterion-wise weighted Grade Point (CrWGPi) | E5: Criterion- wise Grade Point Averages (CrWGPi/Wi) | G5: Range of Institutional Cumulative Grade Point Average (CGPA) | H5: Letter Grade | I5: Status
A6: 1 | B6: Curricular Aspects | C6: 70 | D6: =SUM('Qn (34m)'!O3:O6) -> 80 | E6: =D6/C6 -> 1.1428571 | G6: 3.51-4.00 | H6: A++ | I6: Accredited
A7: 2 | B7: Teaching-learning and Evaluation | C7: 225 | D7: =SUM('Qn (34m)'!O7:O13) -> 585 | E7: =D7/C7 -> 2.6 | G7: 3.26-3.500 | H7: A+ | I7: Accredited
A8: 3 | B8: Research, Innovations and Extension | C8: 80 | D8: =SUM('Qn (34m)'!O14:O19) -> 115 | E8: =D8/C8 -> 1.4375 | G8: 3.01-3.25 | H8: A | I8: Accredited
A9: 4 | B9: Infrastructure and Learning Resources | C9: 40 | D9: =SUM('Qn (34m)'!O20:O22) -> 60 | E9: =D9/C9 -> 1.5 | G9: 2.76-3.00 | H9: B++ | I9: Accredited
A10: 5 | B10: Student Support and Progression | C10: 130 | D10: =SUM('Qn (34m)'!O23:O30) -> 245 | E10: =D10/C10 -> 1.8846154 | G10: 2.51-2.75 | H10: B+ | I10: Accredited
A11: 6 | B11: Governance, Leadership and Management | C11: 46 | D11: =SUM('Qn (34m)'!O31:O34) -> 61 | E11: =D11/C11 -> 1.326087 | G11: 2.01-2.50 | H11: B | I11: Accredited
A12: 7 | B12: Institutional Values and Best Practices | C12: 30 | D12: =SUM('Qn (34m)'!O35:O36) -> 100 | E12: =D12/C12 -> 3.3333333 | G12: 1.51-2.00 | H12: C | I12: Accredited
A13: Total | C13: =SUM(C6:C12) -> 621 | D13: =SUM(D6:D12) -> 1246 | E13: =D13/C13 -> 2.0064412 | G13: ≤ 1.50 | H13: D | I13: Not Accredited
A15: =D13/C13 -> 2.0064412
A17: =IF(AND($A$15<=4,$A$15>=3.51),"A++",IF(AND($A$15<=3.5,$A$15>=3.26),"A+",IF(AND($A$15<=3.25,$A$15>3.01),"A",IF(AND($A$15<=3,$A$15>=2.76),"B++",IF(AND($A$15<=2.75,$A$15>=2.51),"B+",IF(AND($A$15<=2.5,$A$15>=2),"B",IF(AND($A$15<=2,$A$15>=1.51),"C","D"))))))) -> B
A19: Criterion wise - Quantitative Grade Sheet
A20: Name of the Institution: | C20: ='Affiliated(55m)'!$J$2 -> Institute Name
A21: Type of the Institution: | C21: ='Affiliated(55m)'!$K$1 -> Affiliated
A22: Dates of Visit:
A23: No | B23: Criteria and Key Indicators | C23: Key Indicator Weightage (Wi) | D23: Key Indicator Wise Weighted Grade Points (KIWGP)i
A24: Criterion 1: Curricular Aspects
A25: 1.2 | B25: Academic Flexibility | C25: 30 | D25: 0
A26: 1.3 | B26: Curriculum Enrichment | C26: 20 | D26: =SUM('Qn (34m)'!M5) -> 0
A27: 1.4 | B27: Feedback System | C27: 20 | D27: =SUM('Qn (34m)'!M6) -> 80
A28: Total | C28: =SUM(C25:C27) -> 70 | D28: =SUM(D25:D27) -> 80
D29: Grade | E29: =IF(AND($E$28<=4,$E$28>=3.51),"A++",IF(AND($E$28<=3.5,$E$28>=3.26),"A+",IF(AND($E$28<=3.25,$E$28>3.01),"A",IF(AND($E$28<=3,$E$28>=2.76),"B++",IF(AND($E$28<=2.75,$E$28>=2.51),"B+",IF(AND($E$28<=2.5,$E$28>=2.01),"B",IF(AND($E$28<=2,$E$28>=1.51),"C","D"))))))) -> D
A30: =80/70 -> 1.1428571
A31: Criterion 2: Teaching-learning and Evaluation
A32: 2.1 | B32: Student Enrollment and Profile | C32: 40 | D32: =SUM('Qn (34m)'!M7:M8) -> 140
A33: 2.2 | B33: Catering to Student Diversity | C33: 40 | D33: =SUM('Qn (34m)'!M9) -> 120
A34: 2.4 | B34: Teacher Profile and Quality | C34: 40 | D34: =SUM('Qn (34m)'!M10:M11) -> 85
A35: 2.6 | B35: Student Performance and Learning Outcomes | C35: 45 | D35: =SUM('Qn (34m)'!M12) -> 180
A36: 2.7 | B36: Student Satisfaction Survey | C36: 60 | D36: =SUM('Qn (34m)'!M13) -> 60
A37: Total | C37: =SUM(C32:C36) -> 225 | D37: =SUM(D32:D36) -> 585
A38: =D37/C37 -> 2.6
A39: Criterion 3: Research, Innovations and Extension
A40: 3.1 | B40: Resource Mobilization for Research | C40: 10 | D40: =SUM('Qn (34m)'!M14) -> 0
A41: 3.2 | B41: Innovation Ecosystem | C41: 5 | D41: =SUM('Qn (34m)'!M15) -> 5
A42: 3.3 | B42: Research Publications and Awards | C42: 25 | D42: =SUM('Qn (34m)'!M16:M17) -> 30
A43: 3.4 | B43: Extension Activities | C43: 20 | D43: =SUM('Qn (34m)'!M18) -> 80
...

Sheet Ql (21m)
