Workbook

Sheet Extended Profile (EP)
A1: Criteria | B1: Metric Num | C1: Metric Description
A2: 1 Student: | B2: 1.1 | C2: Number of students year wise during the last five years
B3: Year
B4: Number
A5: 2 Teachers: | B5: 2.1 | C5: Number of full time teachers during the last five years (Without repeat count):
B6: 2.2 | C6: Number of full time teachers year wise during the last five years
B7: Year
B8: Number
A9: 3. Expenditure: | B9: 3.1 | C9: Expenditure excluding salary component year wise during the last five years (INR in lakhs)
B10: Year
B11: INR in Lakhs

Sheet Response Score Calc.
A2: S. No | B2: Criteria © | C2: Key Indicator (KI) | D2: Metric (M) Type | E2: Metric (M) Num | F2: Metric (M) Description | G2: M Wt | H2: HEI I/P (Response) | I2: P Response Score
A3: =SUBTOTAL(3,$B$3:B3) -> 1 | B3: 1. Curricular Aspects | C3: 1.2 Academic Flexibility | D3: QlM | E3: 1.1.1 | F3: Curricula developed and implemented have relevance to the local, national, regional and global developmental needs which is reflected in Programme outcomes (POs), Programme Specific outcomes (PSOs) and Course Outcomes (COs) of the Programmes offered by the Institution Write description in maximum of 500 words | G3: 20
A4: =SUBTOTAL(3,$B$3:B4) -> 2 | B4: 1. Curricular Aspects | C4: 1.2 Academic Flexibility | D4: QnM | E4: 1.1.2 | F4: Percentage of Programmes where syllabus revision was carried out during the last five years 1.1.2.1: How many Programmes were revised out of total number of Programmes offered during the same period within last five years? 1.1.2.2 : Number of all Programmes offered by the institution during the last five years | G4: 20 | H4: 4 (= 100%)
A5: =SUBTOTAL(3,$B$3:B5) -> 3 | B5: 1. Curricular Aspects | C5: 1.3 Curriculum Enrichment | D5: QnM | E5: 1.1.3 | F5: Average percentage of courses having focus on employability/ entrepreneurship/ skill development offered by the institution during the last five years 1.1.3.1: Number of courses having focus on employability/ entrepreneurship/ skill development year wise during last five years | G5: 10 | H5: 4 (= 100%)
A6: =SUBTOTAL(3,$B$3:B6) -> 4 | B6: 1. Curricular Aspects | C6: 1.4 Feedback System | D6: QnM | E6: 1.2.1 | F6: Percentage of new courses introduced of the total number of courses across all programs offered during the last five years 1.2.1.1: How many new courses are introduced within the last five years 1.2.1.2 : Number of courses offered by the institution across all Programmes during the last five years | G6: 20 | H6: 4 (> 50%)
A7: =SUBTOTAL(3,$B$3:B7) -> 5 | B7: 2. Teaching-Learning and Evaluation | C7: 2.1 Student Enrolment and Profile | D7: QnM | E7: 1.2.2 | F7: Percentage of Programmes in which Choice Based Credit System (CBCS)/elective course system has been implemented (Data for the latest completed academic year ) 1.2.2.1: Number of Programmes in which CBCS/Elective course system implemented. | G7: 20 | H7: 4 (= 100%)
A8: =SUBTOTAL(3,$B$3:B8) -> 6 | B8: 2. Teaching-Learning and Evaluation | C8: 2.1 Student Enrolment and Profile | D8: QlM | E8: 1.3.1 | F8: Institution integrates crosscutting issues relevant to Professional Ethics, Gender, Human Values, Environment and Sustainability, Human Values into the Curriculum Write description in maximum of 500 words | G8: 10
A9: =SUBTOTAL(3,$B$3:B9) -> 7 | B9: 2. Teaching-Learning and Evaluation | C9: 2.2 Student Teacher Ratio | D9: QnM | E9: 1.3.2 | F9: Number of value-added courses for imparting transferable and life skills offered during last five years 1.3.2.1: How many new value-added courses are added within the last 5 years | G9: 10 | H9: 4 (> 100)
A10: =SUBTOTAL(3,$B$3:B10) -> 8 | B10: 2. Teaching-Learning and Evaluation | C10: 2.4 Teacher Profile and Quality | D10: QnM | E10: 1.3.3 | F10: Average Percentage of students enrolled in the courses under 1.3.2 above 1.3.3.1: Number of students enrolled in value added courses (beyond the curriculum) offered year wise during last five year | G10: 10 | H10: 4 (> 75%)
A11: =SUBTOTAL(3,$B$3:B11) -> 9 | B11: 2. Teaching-Learning and Evaluation | C11: 2.4 Teacher Profile and Quality | D11: QnM | E11: 1.3.4 | F11: Percentage of students undertaking field projects/ internships / student projects (Data for the latest completed academic year) 1.3.4.1: Number of students undertaking field projects / internships / student projects | G11: 10 | H11: 4 (> 90%)
A12: =SUBTOTAL(3,$B$3:B12) -> 10 | B12: 2. Teaching-Learning and Evaluation | C12: 2.6 Student Performance and Learning Outcomes | D12: QnM | E12: 1.4.1 | F12: Structured feedback for design and review of syllabus ( semester wise / year wise) is obtained from 1) Students, 2) Teachers, 3) Employers, 4) Alumni | G12: 10 | H12: 4 (all of the Above)
A13: =SUBTOTAL(3,$B$3:B13) -> 11 | B13: 2. Teaching-Learning and Evaluation | C13: 2.7 Student Satisfaction Survey | D13: QnM | E13: 1.4.2 | F13: The feedback system of the Institution comprises of the following : A. Feedback collected, analysed and action taken and report made available on website B. Feedback collected, analysed and action taken C. Feedback collected and analysed D. Feedback collected E. Feedback not obtained | G13: 10 | H13: 4 (all of the Above)
A14: =SUBTOTAL(3,$B$3:B14) -> 12 | B14: 3. Research, Innovations and Extension | C14: 3.1 Resource Mobilization for Research | D14: QnM | E14: 2.1.1 | F14: Average Enrolment percentage (Average of last five years) 2.1.1.1: Number of students admitted year wise during last five years 2.1.1.2: Number of sanctioned seats year wise during last five years | G14: 10 | H14: 4 (> 90)
A15: =SUBTOTAL(3,$B$3:B15) -> 13 | B15: 3. Research, Innovations and Extension | C15: 3.2 Innovation Ecosystem | D15: QnM | E15: 2.1.2 | F15: Average percentage of seats filled against reserved categories (SC, ST, OBC, Divyangjan, etc. as per applicable reservation policy ) during the last five years ( exclusive of supernumerary seats) 2.1.2.1: Number of actual students admitted from the reserved categories year wise during last five years | G15: 10 | H15: 4 (> 90)
A16: =SUBTOTAL(3,$B$3:B16) -> 14 | B16: 3. Research, Innovations and Extension | C16: 3.3 Research Publications and Awards | D16: QlM | E16: 2.2.1 | F16: The institution assesses the learning levels of the students and organises special Programmes for advanced learners and slow learners. Write description in of 500 words | G16: 15
A17: =SUBTOTAL(3,$B$3:B17) -> 15 | B17: 3. Research, Innovations and Extension | C17: 3.3 Research Publications and Awards | D17: QnM | E17: 2.2.2 | F17: Student - Full time teacher ratio (Data for the latest completed academic year) | G17: 15 | H17: 4 (15 : 01)
A18: =SUBTOTAL(3,$B$3:B18) -> 16 | B18: 3. Research, Innovations and Extension | C18: 3.4 Extension Activities | D18: QlM | E18: 2.3.1 | F18: Student centric methods, such as experiential learning, participative learning and problem solving methodologies are used for enhancing learning experiences Write description in maximum of 500 words | G18: 15
A19: =SUBTOTAL(3,$B$3:B19) -> 17 | B19: 3. Research, Innovations and Extension | C19: 3.5 Collaboration | D19: QlM | E19: 2.3.2 | F19: Teachers use ICT enabled tools including online resources for effective teaching and learning process Write description in maximum of 500 words | G19: 15
A20: =SUBTOTAL(3,$B$3:B20) -> 18 | B20: 4. Infrastructure and Learning Resources | C20: 4.1 Physical Facilities | D20: QnM | E20: 2.3.3 | F20: Ratio of students to mentor for academic and other related issues (Data for the latest completed academic year ) 2.3.3.1: Number of mentors Number of students assigned to each Mentor | G20: 10 | H20: 4 (15-20)
A21: =SUBTOTAL(3,$B$3:B21) -> 19 | B21: 4. Infrastructure and Learning Resources | C21: 4.3 IT Infrastructure | D21: QlM | E21: 2.3.4 | F21: Preparation and adherence of Academic Calendar and Teaching plans by the institution Describe the Preparation and adherence to Academic Calendar and Teaching plans by the institution within the minimum of 500 Characters and maximum of 500 words. | G21: 10
A22: =SUBTOTAL(3,$B$3:B22) -> 20 | B22: 4. Infrastructure and Learning Resources | C22: 4.4 Maintenance of Campus Infrastructure | D22: QnM | E22: 2.4.1 | F22: Average percentage of full time teachers against sanctioned posts during the last five years | G22: 15 | H22: 4 (100)
A23: =SUBTOTAL(3,$B$3:B23) -> 21 | B23: 5. Student Support and Progression | C23: 5.1 Student Support | D23: QnM | E23: 2.4.2 | F23: Average percentage of full time teachers with Ph.D. / D.M. / M.Ch. / D.N.B Super speciality / D.Sc. / D.Litt. during the last five years 2.4.2.1: Number of full time teachers with Ph.D./ D.M. / M.Ch. / D.N.B Super speciality / D.Sc. / D.Litt. year wise during last five years | G23: 20 | H23: 4 (> 80)
A24: =SUBTOTAL(3,$B$3:B24) -> 22 | B24: 5. Student Support and Progression | C24: 5.1 Student Support | D24: QnM | E24: 2.4.3 | F24: Average teaching experience of full time teachers in the same institution (Data for the latest completed academic year in number of years 2.4.3.1: Total experience of full-time teachers | G24: 15 | H24: 4 (> 15)
A25: =SUBTOTAL(3,$B$3:B25) -> 23 | B25: 5. Student Support and Progression | C25: 5.1 Student Support | D25: QnM | E25: 2.5.1 | F25: Average number of days from the date of last semester-end/ year- end examination till the declaration of results during the last five years 2.5.1.1: Number of days from the date of last semester-end/ year- end examination till the declaration of results year wise during the last five years | G25: 20 | H25: 4 (< 10-15)
A26: =SUBTOTAL(3,$B$3:B26) -> 24 | B26: 5. Student Support and Progression | C26: 5.1 Student Support | D26: QnM | E26: 2.5.2 | F26: Average percentage of student complaints/grievances about evaluation against total number appeared in the examinations during the last five years 2.5.2.1: Number of complaints/grievances about evaluation year wise during last five years | G26: 15 | H26: 4 (< 1)
A27: =SUBTOTAL(3,$B$3:B27) -> 25 | B27: 5. Student Support and Progression | C27: 5.2 Student Progression | D27: QlM | E27: 2.5.3 | F27: IT integration and reforms in the examination procedures and processes including Continuous Internal Assessment (CIA) have brought in considerable improvement in Examination Management System (EMS) of the Institution Describe the examination reforms with reference to the following within a minimum of 500 words and maximum 1000 words: | G27: 15
A28: =SUBTOTAL(3,$B$3:B28) -> 26 | B28: 5. Student Support and Progression | C28: 5.2 Student Progression | D28: QlM | E28: 2.6.1 | F28: Programme outcomes and course outcomes for all Programmes offered by the institution are stated and displayed on website and communicated to teachers and students Describe Course Outcomes (COs) for all courses and mechanism of communication within a maximum of 500 words | G28: 20
A29: =SUBTOTAL(3,$B$3:B29) -> 27 | B29: 5. Student Support and Progression | C29: 5.3 Student Participation and Activities | D29: QlM | E29: 2.6.2 | F29: Attainment of program outcomes and course outcomes are evaluated by the institution Describe the method of measuring attainment of POs , PSOs and COs in not more than 500 words and the level of attainment of POs , PSOs and COs. | G29: 10
A30: =SUBTOTAL(3,$B$3:B30) -> 28 | B30: 5. Student Support and Progression | C30: 5.3 Student Participation and Activities | D30: QnM | E30: 2.6.3 | F30: Pass percentage of students (Data for the latest completed academic year) 2.6.3.1: Total number of final year students who passed the examination conducted by Institution. 2.6.3.2: Total number of final year students who appeared for the examination | G30: 20 | H30: 4 (> 90%)
A31: =SUBTOTAL(3,$B$3:B31) -> 29 | B31: 6. Governance, Leadership and Management | C31: 6.2 Strategy Development and Deployment | D31: QnM | E31: 2.7.1 | F31: Online student satisfaction survey regarding to teaching learning process. (Online survey to be conducted) | G31: 50 | H31: 3.5 (>3.5)
A32: =SUBTOTAL(3,$B$3:B32) -> 30 | B32: 6. Governance, Leadership and Management | C32: 6.3 Faculty Empowerment Strategies | D32: QlM | E32: 3.1.1 | F32: The institution Research facilities are frequently updated and there is well defined policy for promotion of research which is uploaded on the institutional website and implemented Write description in maximum of 500 words | G32: 6
A33: =SUBTOTAL(3,$B$3:B33) -> 31 | B33: 6. Governance, Leadership and Management | C33: 6.3 Faculty Empowerment Strategies | D33: QnM | E33: 3.1.2 | F33: The institution provides seed money to its teachers for research (Average per year) 3.1.2.1: The amount of seed money provided by institution to its teachers for research year wise during last five years (INR in lakhs) | G33: 8 | H33: 4 (> 10L)
A34: =SUBTOTAL(3,$B$3:B34) -> 32 | B34: 6. Governance, Leadership and Management | C34: 6.5 Internal Quality Assurance System (IQAS) | D34: QnM | E34: 3.1.3 | F34: Percentage of teachers awarded national / international fellowship for advanced studies/research during the last five years 3.1.3.1: The number of teachers awarded national / international fellowship for advanced studies / research year wise during last five years | G34: 6 | H34: 4 (>10%)
A35: =SUBTOTAL(3,$B$3:B35) -> 33 | B35: 7. Institutional Values and Best Practices | C35: 7.1 Institutional Values and Social Responsibilities | D35: QnM | E35: 3.2.1 | F35: Grants received from Government and non-governmental agencies for research projects, endowments, Chairs in the institution during the last five years (INR in Lakhs) 3.2.1.1: Total Grants from Government and non-governmental agencies for research projects , endowments, Chairs in the institution during the last five years (INR in Lakhs) | G35: 2 | H35: 4 (> 300L)
A36: =SUBTOTAL(3,$B$3:B36) -> 34 | B36: 7. Institutional Values and Best Practices | C36: 7.1 Institutional Values and Social Responsibilities | D36: QnM | E36: 3.2.2 | F36: Percentage of teachers having research projects during the last five years 3.2.2.1: Number of teachers having research projects during the last five years | G36: 2 | H36: 4 (> 3)
D37: QnM | E37: 3.2.3 | F37: Percentage of teachers recognised as research guides 3.2.3.1: Number of teachers recognised as research guides | G37: 3 | H37: 4 (> 20)
D38: QnM | E38: 3.2.4 | F38: Average percentage of departments having Research projects funded by government and non-government agencies during the last five years 3.2.4.1: Number of departments having Research projects funded by government and non-government agencies during the last five years | G38: 3 | H38: 4 (> 40)
D39: QlM | E39: 3.3.1 | F39: Institution has created an eco system for innovations, creation and transfer of knowledge supported by dedicated centers for research, entrepreneurship, community orientation, Incubation etc. Write description in maximum of 500 words | G39: 5
D40: QnM | E40: 3.3.2 | F40: Number of workshops/seminars conducted on Research Methodology, Intellectual Property Rights (IPR), entrepreneurship and skills development during the last five years 3.3.2.1: Total number of workshops/seminars conducted on Research Methodology, Intellectual Property Rights (IPR) and entrepreneurship and skills development year wise during last five years | G40: 5 | H40: 4 (> 80)
D41: QnM | E41: 3.4.1 | F41: The Institution ensures implementation of its stated Code of Ethics for research through the following: 1. Inclusion of research ethics in the research methodology course work 2. Presence of Ethics committee 3. Plagiarism check through software 4. Research Advisory Committee | G41: 5 | H41: 4 (all of the Above)
...

Sheet Autonomous 107m
J1: RESPONSE | K1: Autonomous
A2: S. No | B2: Criteria © | C2: Key Indicator (KI) | D2: Metric (M) Type | E2: Metric (M) Num | F2: Metric (M) Description | G2: M Wt | H2: KI Wt | I2: © Wt | J2: Institute Name | K2: Metric Grade scale (0-4) | L2: M wise weighted Grade points | M2: KIwise weighted Grade points | N2: KIwise weighted Grade points Average | O2: ©Wise Weighted Average | P2: ©Wise Weighted Grade Point Average
A3: 1 | B3: 1. Curricular Aspects | C3: 1.1 Curriculum Planning and Implementation | D3: QlM | E3: 1.1.1 | F3: Curricula developed and implemented have relevance to the local, national, regional and global developmental needs which is reflected in Programme outcomes (POs), Programme Specific outcomes (PSOs) and Course Outcomes (COs) of the Programmes offered by the Institution Write description in maximum of 500 words | G3: 20 | H3: 50 | I3: 150 | L3: =K3*G3 -> 0 | M3: =SUM(L3:L5) -> 120 | N3: =M3/H3 -> 2.4 | O3: =SUM(M3:M13) -> 320 | P3: =O3/I3 -> 2.1333333
A4: 2 | B4: 1. Curricular Aspects | C4: 1.1 Curriculum Planning and Implementation | D4: QnM | E4: 1.1.2 | F4: Percentage of Programmes where syllabus revision was carried out during the last five years 1.1.2.1: How many Programmes were revised out of total number of Programmes offered during the same period within last five years? 1.1.2.2 : Number of all Programmes offered by the institution during the last five years | G4: 20 | J4: 92.86 | K4: =IF(J4>80,4,IF(AND(J4<=80,J4>60),3,IF(AND(J4<=60,J4>40),2,IF(AND(J4<=40,J4>20),1,IF(J4<=20,0))))) -> 4 | L4: =K4*G4 -> 80
A5: 3 | B5: 1. Curricular Aspects | C5: 1.1 Curriculum Planning and Implementation | D5: QnM | E5: 1.1.3 | F5: Average percentage of courses having focus on employability/ entrepreneurship/ skill development offered by the institution during the last five years 1.1.3.1: Number of courses having focus on employability/ entrepreneurship/ skill development year wise during last five years | G5: 10 | J5: 84.19 | K5: =IF(J5>80,4,IF(AND(J5<=80,J5>60),3,IF(AND(J5<=60,J5>40),2,IF(AND(J5<=40,J5>20),1,IF(J5<=20,0))))) -> 4 | L5: =K5*G5 -> 40
A6: 4 | B6: 1. Curricular Aspects | C6: 1.2 Academic Flexibility | D6: QnM | E6: 1.2.1 | F6: Percentage of new courses introduced of the total number of courses across all programs offered during the last five years 1.2.1.1: How many new courses are introduced within the last five years 1.2.1.2 : Number of courses offered by the institution across all Programmes during the last five years | G6: 20 | H6: 40 | J6: 38.71 | K6: =IF(J6>80,4,IF(AND(J6<=80,J6>60),3,IF(AND(J6<=60,J6>40),2,IF(AND(J6<=40,J6>20),1,IF(J6<=20,0))))) -> 1 | L6: =K6*G6 -> 20 | M6: =SUM(L6:L7) -> 100 | N6: =M6/H6 -> 2.5
A7: 5 | B7: 1. Curricular Aspects | C7: 1.2 Academic Flexibility | D7: QnM | E7: 1.2.2 | F7: Percentage of Programmes in which Choice Based Credit System (CBCS)/elective course system has been implemented (Data for the latest completed academic year ) 1.2.2.1: Number of Programmes in which CBCS/Elective course system implemented. | G7: 20 | J7: 81.25 | K7: =IF(J7>80,4,IF(AND(J7<=80,J7>60),3,IF(AND(J7<=60,J7>40),2,IF(AND(J7<=40,J7>20),1,IF(J7<=20,0))))) -> 4 | L7: =K7*G7 -> 80
A8: 6 | B8: 1. Curricular Aspects | C8: 1.3 Curriculum Enrichment | D8: QlM | E8: 1.3.1 | F8: Institution integrates crosscutting issues relevant to Professional Ethics, Gender, Human Values, Environment and Sustainability, Human Values into the Curriculum Write description in maximum of 500 words | G8: 10 | H8: 40 | L8: =K8*G8 -> 0 | M8: =SUM(L8:L11) -> 50 | N8: =M8/H8 -> 1.25
A9: 7 | B9: 1. Curricular Aspects | C9: 1.3 Curriculum Enrichment | D9: QnM | E9: 1.3.2 | F9: Number of value-added courses for imparting transferable and life skills offered during last five years 1.3.2.1: How many new value-added courses are added within the last 5 years | G9: 10 | J9: 87 | K9: =IF(J9>80,4,IF(AND(J9<=80,J9>60),3,IF(AND(J9<=60,J9>40),2,IF(AND(J9<=40,J9>20),1,IF(J9<=20,0))))) -> 4 | L9: =K9*G9 -> 40
A10: 8 | B10: 1. Curricular Aspects | C10: 1.3 Curriculum Enrichment | D10: QnM | E10: 1.3.3 | F10: Average Percentage of students enrolled in the courses under 1.3.2 above 1.3.3.1: Number of students enrolled in value added courses (beyond the curriculum) offered year wise during last five year | G10: 10 | J10: 32.64 | K10: =IF(J10>80,4,IF(AND(J10<=80,J10>60),3,IF(AND(J10<=60,J10>40),2,IF(AND(J10<=40,J10>20),1,IF(J10<=20,0))))) -> 1 | L10: =K10*G10 -> 10
A11: 9 | B11: 1. Curricular Aspects | C11: 1.3 Curriculum Enrichment | D11: QnM | E11: 1.3.4 | F11: Percentage of students undertaking field projects/ internships / student projects (Data for the latest completed academic year) 1.3.4.1: Number of students undertaking field projects / internships / student projects | G11: 10 | J11: 61.81 | K11: =IF(EXACT(J11,"A"),4,IF(EXACT(J11,"B"),3,IF(EXACT(J11,"C"),2,IF(EXACT(J11,"D"),1,0)))) -> 0 | L11: =K11*G11 -> 0
A12: 10 | B12: 1. Curricular Aspects | C12: 1.4 Feedback System | D12: QnM | E12: 1.4.1 | F12: Structured feedback for design and review of syllabus ( semester wise / year wise) is obtained from 1) Students, 2) Teachers, 3) Employers, 4) Alumni | G12: 10 | H12: 20 | J12: B | K12: =IF(EXACT(J12,"A"),4,IF(EXACT(J12,"B"),3,IF(EXACT(J12,"C"),2,IF(EXACT(J12,"D"),1,0)))) -> 3 | L12: =K12*G12 -> 30 | M12: =SUM(L12:L13) -> 50 | N12: =M12/H12 -> 2.5
A13: 11 | B13: 1. Curricular Aspects | C13: 1.4 Feedback System | D13: QnM | E13: 1.4.2 | F13: The feedback system of the Institution comprises of the following : A. Feedback collected, analysed and action taken and report made available on website B. Feedback collected, analysed and action taken C. Feedback collected and analysed D. Feedback collected E. Feedback not obtained | G13: 10 | J13: C | K13: =IF(EXACT(J13,"A"),4,IF(EXACT(J13,"B"),3,IF(EXACT(J13,"C"),2,IF(EXACT(J13,"D"),1,0)))) -> 2 | L13: =K13*G13 -> 20
A14: 12 | B14: 2. Teaching-Learning and Evaluation | C14: 2.1 Student Enrolment and Profile | D14: QnM | E14: 2.1.1 | F14: Average Enrolment percentage (Average of last five years) 2.1.1.1: Number of students admitted year wise during last five years 2.1.1.2: Number of sanctioned seats year wise during last five years | G14: 10 | H14: 20 | I14: 300 | J14: 85.42 | K14: =IF(J14>80,4,IF(AND(J14<=80,J14>60),3,IF(AND(J14<=60,J14>40),2,IF(AND(J14<=40,J14>20),1,IF(J14<=20,0))))) -> 4 | L14: =K14*G14 -> 40 | M14: =SUM(L14:L15) -> 80 | N14: =M14/H14 -> 4 | O14: =SUM(M14:M31) -> 240 | P14: =O14/I14 -> 0.8
A15: 13 | B15: 2. Teaching-Learning and Evaluation | C15: 2.1 Student Enrolment and Profile | D15: QnM | E15: 2.1.2 | F15: Average percentage of seats filled against reserved categories (SC, ST, OBC, Divyangjan, etc. as per applicable reservation policy ) during the last five years ( exclusive of supernumerary seats) 2.1.2.1: Number of actual students admitted from the reserved categories year wise during last five years | G15: 10 | J15: 97.91 | K15: =IF(J15>80,4,IF(AND(J15<=80,J15>60),3,IF(AND(J15<=60,J15>40),2,IF(AND(J15<=40,J15>20),1,IF(J15<=20,0))))) -> 4 | L15: =K15*G15 -> 40
A16: 14 | B16: 2. Teaching-Learning and Evaluation | C16: 2.2 Catering to Student Diversity | D16: QlM | E16: 2.2.1 | F16: The institution assesses the learning levels of the students and organises special Programmes for advanced learners and slow learners. Write description in of 500 words | G16: 15 | H16: 30 | L16: =K16*G16 -> 0 | M16: =SUM(L16:L17) -> 0 | N16: =M16/H16 -> 0
A17: 15 | B17: 2. Teaching-Learning and Evaluation | C17: 2.2 Catering to Student Diversity | D17: QnM | E17: 2.2.2 | F17: Student - Full time teacher ratio (Data for the latest completed academic year) | G17: 15 | J17: 16.13 | K17: =IF(J17>80,4,IF(AND(J17<=80,J17>60),3,IF(AND(J17<=60,J17>40),2,IF(AND(J17<=40,J17>20),1,IF(J17<=20,0))))) -> 0 | L17: =K17*G17 -> 0
A18: 16 | B18: 2. Teaching-Learning and Evaluation | C18: 2.3 Teaching-Learning Process | D18: QlM | E18: 2.3.1 | F18: Student centric methods, such as experiential learning, participative learning and problem solving methodologies are used for enhancing learning experiences Write description in maximum of 500 words | G18: 15 | H18: 50 | L18: =K18*G18 -> 0 | M18: =SUM(L18:L21) -> 0 | N18: =M18/H18 -> 0
A19: 17 | B19: 2. Teaching-Learning and Evaluation | C19: 2.3 Teaching-Learning Process | D19: QlM | E19: 2.3.2 | F19: Teachers use ICT enabled tools including online resources for effective teaching and learning process Write description in maximum of 500 words | G19: 15 | L19: =K19*G19 -> 0
A20: 18 | B20: 2. Teaching-Learning and Evaluation | C20: 2.3 Teaching-Learning Process | D20: QnM | E20: 2.3.3 | F20: Ratio of students to mentor for academic and other related issues (Data for the latest completed academic year ) 2.3.3.1: Number of mentors Number of students assigned to each Mentor | G20: 10 | J20: 0.79236111 | K20: =IF(J20>80,4,IF(AND(J20<=80,J20>60),3,IF(AND(J20<=60,J20>40),2,IF(AND(J20<=40,J20>20),1,IF(J20<=20,0))))) -> 0 | L20: =K20*G20 -> 0
A21: 19 | B21: 2. Teaching-Learning and Evaluation | C21: 2.3 Teaching-Learning Process | D21: QlM | E21: 2.3.4 | F21: Preparation and adherence of Academic Calendar and Teaching plans by the institution Describe the Preparation and adherence to Academic Calendar and Teaching plans by the institution within the minimum of 500 Characters and maximum of 500 words. | G21: 10 | L21: =K21*G21 -> 0
A22: 20 | B22: 2. Teaching-Learning and Evaluation | C22: 2.4 Teacher Profile and Quality | D22: QnM | E22: 2.4.1 | F22: Average percentage of full time teachers against sanctioned posts during the last five years | G22: 15 | H22: 50 | J22: 99.34 | K22: =IF(J22>80,4,IF(AND(J22<=80,J22>60),3,IF(AND(J22<=60,J22>40),2,IF(AND(J22<=40,J22>20),1,IF(J22<=20,0))))) -> 4 | L22: =K22*G22 -> 60 | M22: =SUM(L22:L24) -> 60 | N22: =M22/H22 -> 1.2
A23: 21 | B23: 2. Teaching-Learning and Evaluation | C23: 2.4 Teacher Profile and Quality | D23: QnM | E23: 2.4.2 | F23: Average percentage of full time teachers with Ph.D. / D.M. / M.Ch. / D.N.B Super speciality / D.Sc. / D.Litt. during the last five years 2.4.2.1: Number of full time teachers with Ph.D./ D.M. / M.Ch. / D.N.B Super speciality / D.Sc. / D.Litt. year wise during last five years | G23: 20 | J23: 11.09 | K23: =IF(J23>80,4,IF(AND(J23<=80,J23>60),3,IF(AND(J23<=60,J23>40),2,IF(AND(J23<=40,J23>20),1,IF(J23<=20,0))))) -> 0 | L23: =K23*G23 -> 0
A24: 22 | B24: 2. Teaching-Learning and Evaluation | C24: 2.4 Teacher Profile and Quality | D24: QnM | E24: 2.4.3 | F24: Average teaching experience of full time teachers in the same institution (Data for the latest completed academic year in number of years 2.4.3.1: Total experience of full-time teachers | G24: 15 | J24: 5.69 | K24: =IF(J24>80,4,IF(AND(J24<=80,J24>60),3,IF(AND(J24<=60,J24>40),2,IF(AND(J24<=40,J24>20),1,IF(J24<=20,0))))) -> 0 | L24: =K24*G24 -> 0
A25: 23 | B25: 2. Teaching-Learning and Evaluation | C25: 2.5 Evaluation Process and Reforms | D25: QnM | E25: 2.5.1 | F25: Average number of days from the date of last semester-end/ year- end examination till the declaration of results during the last five years 2.5.1.1: Number of days from the date of last semester-end/ year- end examination till the declaration of results year wise during the last five years | G25: 20 | H25: 50 | J25: 21 | K25: =IF(J25>80,4,IF(AND(J25<=80,J25>60),3,IF(AND(J25<=60,J25>40),2,IF(AND(J25<=40,J25>20),1,IF(J25<=20,0))))) -> 1 | L25: =K25*G25 -> 20 | M25: =SUM(L25:L27) -> 20 | N25: =M25/H25 -> 0.4
A26: 24 | B26: 2. Teaching-Learning and Evaluation | C26: 2.5 Evaluation Process and Reforms | D26: QnM | E26: 2.5.2 | F26: Average percentage of student complaints/grievances about evaluation against total number appeared in the examinations during the last five years 2.5.2.1: Number of complaints/grievances about evaluation year wise during last five years | G26: 15 | J26: 12.61 | K26: =IF(J26>80,4,IF(AND(J26<=80,J26>60),3,IF(AND(J26<=60,J26>40),2,IF(AND(J26<=40,J26>20),1,IF(J26<=20,0))))) -> 0 | L26: =K26*G26 -> 0
A27: 25 | B27: 2. Teaching-Learning and Evaluation | C27: 2.5 Evaluation Process and Reforms | D27: QlM | E27: 2.5.3 | F27: IT integration and reforms in the examination procedures and processes including Continuous Internal Assessment (CIA) have brought in considerable improvement in Examination Management System (EMS) of the Institution Describe the examination reforms with reference to the following within a minimum of 500 words and maximum 1000 words: | G27: 15 | L27: =K27*G27 -> 0
A28: 26 | B28: 2. Teaching-Learning and Evaluation | C28: 2.6 Student Performance and Learning Outcomes | D28: QlM | E28: 2.6.1 | F28: Programme outcomes and course outcomes for all Programmes offered by the institution are stated and displayed on website and communicated to teachers and students Describe Course Outcomes (COs) for all courses and mechanism of communication within a maximum of 500 words | G28: 20 | H28: 50 | L28: =K28*G28 -> 0 | M28: =SUM(L28:L30) -> 80 | N28: =M28/H28 -> 1.6
A29: 27 | B29: 2. Teaching-Learning and Evaluation | C29: 2.6 Student Performance and Learning Outcomes | D29: QlM | E29: 2.6.2 | F29: Attainment of program outcomes and course outcomes are evaluated by the institution Describe the method of measuring attainment of POs , PSOs and COs in not more than 500 words and the level of attainment of POs , PSOs and COs. | G29: 10 | L29: =K29*G29 -> 0
A30: 28 | B30: 2. Teaching-Learning and Evaluation | C30: 2.6 Student Performance and Learning Outcomes | D30: QnM | E30: 2.6.3 | F30: Pass percentage of students (Data for the latest completed academic year) 2.6.3.1: Total number of final year students who passed the examination conducted by Institution. 2.6.3.2: Total number of final year students who appeared for the examination | G30: 20 | J30: 90.9 | K30: =IF(J30>80,4,IF(AND(J30<=80,J30>60),3,IF(AND(J30<=60,J30>40),2,IF(AND(J30<=40,J30>20),1,IF(J30<=20,0))))) -> 4 | L30: =K30*G30 -> 80
A31: 29 | B31: 2. Teaching-Learning and Evaluation | C31: 2.7 Student Satisfaction Survey | D31: QnM | E31: 2.7.1 | F31: Online student satisfaction survey regarding to teaching learning process. (Online survey to be conducted) | G31: 50 | H31: 50 | J31: 3.48 | K31: =IF(EXACT(J31,"A"),4,IF(EXACT(J31,"B"),3,IF(EXACT(J31,"C"),2,IF(EXACT(J31,"D"),1,0)))) -> 0 | L31: =K31*G31 -> 0 | M31: =L31 -> 0 | N31: =M31/H31 -> 0
A32: 30 | B32: 3. Research, Innovations and Extension | C32: 3.1 Promotion of Research and Facilities | D32: QlM | E32: 3.1.1 | F32: The institution Research facilities are frequently updated and there is well defined policy for promotion of research which is uploaded on the institutional website and implemented Write description in maximum of 500 words | G32: 6 | H32: 20 | I32: 150 | L32: =K32*G32 -> 0 | M32: =SUM(L32:L34) -> 0 | N32: =M32/H32 -> 0 | O32: =SUM(M32:M54) -> 114 | P32: =O32/I32 -> 0.76
A33: 31 | B33: 3. Research, Innovations and Extension | C33: 3.1 Promotion of Research and Facilities | D33: QnM | E33: 3.1.2 | F33: The institution provides seed money to its teachers for research (Average per year) 3.1.2.1: The amount of seed money provided by institution to its teachers for research year wise during last five years (INR in lakhs) | G33: 8 | J33: 0 | K33: =IF(J33>80,4,IF(AND(J33<=80,J33>60),3,IF(AND(J33<=60,J33>40),2,IF(AND(J33<=40,J33>20),1,IF(J33<=20,0))))) -> 0 | L33: =K33*G33 -> 0
A34: 32 | B34: 3. Research, Innovations and Extension | C34: 3.1 Promotion of Research and Facilities | D34: QnM | E34: 3.1.3 | F34: Percentage of teachers awarded national / international fellowship for advanced studies/research during the last five years 3.1.3.1: The number of teachers awarded national / international fellowship for advanced studies / research year wise during last five years | G34: 6 | J34: 0.06 | K34: =IF(J34>80,4,IF(AND(J34<=80,J34>60),3,IF(AND(J34<=60,J34>40),2,IF(AND(J34<=40,J34>20),1,IF(J34<=20,0))))) -> 0 | L34: =K34*G34 -> 0
A35: 33 | B35: 3. Research, Innovations and Extension | C35: 3.2 Resource Mobilization for Research | D35: QnM | E35: 3.2.1 | F35: Grants received from Government and non-governmental agencies for research projects, endowments, Chairs in the institution during the last five years (INR in Lakhs) 3.2.1.1: Total Grants from Government and non-governmental agencies for research projects , endowments, Chairs in the institution during the last five years (INR in Lakhs) | G35: 2 | H35: 10 | J35: 116.67 | K35: =IF(J35>80,4,IF(AND(J35<=80,J35>60),3,IF(AND(J35<=60,J35>40),2,IF(AND(J35<=40,J35>20),1,IF(J35<=20,0))))) -> 4 | L35: =K35*G35 -> 8 | M35: =SUM(L35:L38) -> 14 | N35: =M35/H35 -> 1.4
A36: 34 | B36: 3. Research, Innovations and Extension | C36: 3.2 Resource Mobilization for Research | D36: QnM | E36: 3.2.2 | F36: Percentage of teachers having research projects during the last five years 3.2.2.1: Number of teachers having research projects during the last five years | G36: 2 | J36: 1.02 | K36: =IF(J36>80,4,IF(AND(J36<=80,J36>60),3,IF(AND(J36<=60,J36>40),2,IF(AND(J36<=40,J36>20),1,IF(J36<=20,0))))) -> 0 | L36: =K36*G36 -> 0
A37: 35 | B37: 3. Research, Innovations and Extension | C37: 3.2 Resource Mobilization for Research | D37: QnM | E37: 3.2.3 | F37: Percentage of teachers recognised as research guides 3.2.3.1: Number of teachers recognised as research guides | G37: 3 | J37: 3.03 | K37: =IF(J37>80,4,IF(AND(J37<=80,J37>60),3,IF(AND(J37<=60,J37>40),2,IF(AND(J37<=40,J37>20),1,IF(J37<=20,0))))) -> 0 | L37: =K37*G37 -> 0
A38: 36 | B38: 3. Research, Innovations and Extension | C38: 3.2 Resource Mobilization for Research | D38: QnM | E38: 3.2.4 | F38: Average percentage of departments having Research projects funded by government and non-government agencies during the last five years 3.2.4.1: Number of departments having Research projects funded by government and non-government agencies during the last five years | G38: 3 | J38: 43.57 | K38: =IF(J38>80,4,IF(AND(J38<=80,J38>60),3,IF(AND(J38<=60,J38>40),2,IF(AND(J38<=40,J38>20),1,IF(J38<=20,0))))) -> 2 | L38: =K38*G38 -> 6
A39: 37 | B39: 3. Research, Innovations and Extension | C39: 3.3 Innovation Ecosystem | D39: QlM | E39: 3.3.1 | F39: Institution has created an eco system for innovations, creation and transfer of knowledge supported by dedicated centers for research, entrepreneurship, community orientation, Incubation etc. Write description in maximum of 500 words | G39: 5 | H39: 10 | L39: =K39*G39 -> 0 | M39: =SUM(L39:L40) -> 10 | N39: =M39/H39 -> 1
A40: 38 | B40: 3. Research, Innovations and Extension | C40: 3.3 Innovation Ecosystem | D40: QnM | E40: 3.3.2 | F40: Number of workshops/seminars conducted on Research Methodology, Intellectual Property Rights (IPR), entrepreneurship and skills development during the last five years 3.3.2.1: Total number of workshops/seminars conducted on Research Methodology, Intellectual Property Rights (IPR) and entrepreneurship and skills development year wise during last five years | G40: 5 | J40: 43 | K40: =IF(J40>80,4,IF(AND(J40<=80,J40>60),3,IF(AND(J40<=60,J40>40),2,IF(AND(J40<=40,J40>20),1,IF(J40<=20,0))))) -> 2 | L40: =K40*G40 -> 10
...

Sheet 107(Qn&Ql)m-GS
A1: Grade Sheet
A2: Name of the Institution: | C2: ='Autonomous 107m'!$J$2 -> Institute Name
A3: Type of the Institution: | C3: ='Autonomous 107m'!K$1 -> Autonomous
A4: Dates of Visit:
A5: No | B5: Criteria | C5: Weightage (Wi | D5: Criterion-wise weighted Grade Point (CrWGPi) | E5: Criterion- wise Grade Point Averages (CrWGPi/Wi) | G5: Range of Institutional Cumulative Grade Point Average (CGPA) | H5: Letter Grade | I5: Status
A6: 1 | B6: Curricular Aspects | C6: 150 | D6: =SUM('Autonomous 107m'!O3:O13) -> 320 | E6: =D6/C6 -> 2.1333333 | G6: 3.51-4.00 | H6: A++ | I6: Accredited
A7: 2 | B7: Teaching-learning and Evaluation | C7: 300 | D7: =SUM('Autonomous 107m'!O14:O31) -> 240 | E7: =D7/C7 -> 0.8 | G7: 3.26-3.500 | H7: A+ | I7: Accredited
A8: 3 | B8: Research, Innovations and Extension | C8: 150 | D8: =SUM('Autonomous 107m'!O32:O54) -> 114 | E8: =D8/C8 -> 0.76 | G8: 3.01-3.25 | H8: A | I8: Accredited
A9: 4 | B9: Infrastructure and Learning Resources | C9: 100 | D9: =SUM('Autonomous 107m'!O55:O68) -> 64 | E9: =D9/C9 -> 0.64 | G9: 2.76-3.00 | H9: B++ | I9: Accredited
A10: 5 | B10: Student Support and Progression | C10: 100 | D10: =SUM('Autonomous 107m'!O69:O81) -> 104 | E10: =D10/C10 -> 1.04 | G10: 2.51-2.75 | H10: B+ | I10: Accredited
A11: 6 | B11: Governance, Leadership and Management | C11: 100 | D11: =SUM('Autonomous 107m'!O82:O96) -> 94 | E11: =D11/C11 -> 0.94 | G11: 2.01-2.50 | H11: B | I11: Accredited
A12: 7 | B12: Institutional Values and Best Practices | C12: 100 | D12: =SUM('Autonomous 107m'!O97:O109) -> 59 | E12: =D12/C12 -> 0.59 | G12: 1.51-2.00 | H12: C | I12: Accredited
A13: Total | C13: =SUM(C6:C12) -> 1000 | D13: =SUM(D6:D12) -> 995 | E13: =D13/C13 -> 0.995 | G13: ≤ 1.50 | H13: D | I13: Not Accredited
A15: =D13/C13 -> 0.995
A17: =IF(AND($A$15<=4,$A$15>=3.51),"A++",IF(AND($A$15<=3.5,$A$15>=3.26),"A+",IF(AND($A$15<=3.25,$A$15>3.01),"A",IF(AND($A$15<=3,$A$15>=2.76),"B++",IF(AND($A$15<=2.75,$A$15>=2.51),"B+",IF(AND($A$15<=2.5,$A$15>=2.01),"B",IF(AND($A$15<=2,$A$15>=1.51),"C","D"))))))) -> D
A19: Criterion wise - Grade Sheet
A20: Name of the Institution: | C20: ='Autonomous 107m'!$J$2 -> Institute Name
A21: Type of the Institution: | C21: ='Autonomous 107m'!$K$1 -> Autonomous
A22: Dates of Visit:
A23: No | B23: Criteria and Key Indicators | C23: Key Indicator Weightage (Wi) | D23: Key Indicator Wise Weighted Grade Points (KIWGP)i
A24: Criterion 1: Curricular Aspects
A25: 1.1 | B25: Curriculum Planning and Implementation | C25: 50 | D25: =SUM('Autonomous 107m'!M3:M5) -> 120
A26: 1.2 | B26: Academic Flexibility | C26: 40 | D26: =SUM('Autonomous 107m'!M6:M7) -> 100
A27: 1.3 | B27: Curriculum Enrichment | C27: 40 | D27: =SUM('Autonomous 107m'!M8:M11) -> 50
A28: 1.4 | B28: Feedback System | C28: 20 | D28: =SUM('Autonomous 107m'!M12:M13) -> 50
A29: Total | C29: =SUM(C25:C28) -> 150 | D29: =SUM(D25:D28) -> 320
D30: Grade | E30: =IF(AND($E$29<=4,$E$29>=3.51),"A++",IF(AND($E$29<=3.5,$E$29>=3.26),"A+",IF(AND($E$29<=3.25,$E$29>3.01),"A",IF(AND($E$29<=3,$E$29>=2.76),"B++",IF(AND($E$29<=2.75,$E$29>=2.51),"B+",IF(AND($E$29<=2.5,$E$29>=2.01),"B",IF(AND($E$29<=2,$E$29>=1.51),"C","D"))))))) -> D
A31: =80/70 -> 1.1428571
A32: Criterion 2: Teaching-learning and Evaluation
A33: 2.1 | B33: Student Enrollment and Profile | C33: 20 | D33: =SUM('Autonomous 107m'!M14:M15) -> 80
A34: 2.2 | B34: Catering to Student Diversity | C34: 30 | D34: =SUM('Autonomous 107m'!M16:M17) -> 0
A35: 2.3 | B35: Teaching- Learning Process | C35: 50 | D35: =SUM('Autonomous 107m'!M18:M21) -> 0
A36: 2.4 | B36: Teacher Profile and Quality | C36: 50 | D36: =SUM('Autonomous 107m'!M22:M24) -> 60
A37: 2.5 | B37: Evaluation Process and Reforms | C37: 50 | D37: =SUM('Autonomous 107m'!M25:M27) -> 20
A38: 2.6 | B38: Student Performance and Learning Outcomes | C38: 50 | D38: =SUM('Autonomous 107m'!M28:M30) -> 80
A39: 2.7 | B39: Student Satisfaction Survey | C39: 50 | D39: =SUM('Autonomous 107m'!M31) -> 0
A40: Total | C40: =SUM(C33:C39) -> 300 | D40: =SUM(D33:D39) -> 240
A41: =D40/C40 -> 0.8
A42: Criterion 3: Research, Innovations and Extension
A43: 3.1 | B43: Promotion of Research and Facilities | C43: 20 | D43: =SUM('Autonomous 107m'!M32:M34) -> 0
...

Sheet 55m-Gradesheet(GS)
A5: No | B5: Criteria | C5: Weightage (Wi | D5: Criterion-wise weighted Grade Point (CrWGPi) | E5: Criterionwise Grade Point Averages (CrWGPi/Wi) | G5: Range of Institutional Cumulative Grade Point Average (CGPA) | H5: Letter Grade | I5: Status
A6: 1 | B6: Curricular Aspects | C6: 100 | D6: =SUM('Autonomous 107m'!M3:M8) -> 270 | E6: =D6/C6 -> 2.7 | G6: 3.51-4.00 | H6: A++ | I6: Accredited
A7: 2 | B7: Teaching-learning and Evaluation | C7: 350 | D7: =SUM('Autonomous 107m'!M9:M18) -> 130 | E7: =D7/C7 -> 0.37142857 | G7: 3.26-3.500 | H7: A+ | I7: Accredited
A8: 3 | B8: Research, Innovations and Extension | C8: 110 | D8: =SUM('Autonomous 107m'!M19:M27) -> 80 | E8: =D8/C8 -> 0.72727273 | G8: 3.01-3.25 | H8: A | I8: Accredited
A9: 4 | B9: Infrastructure and Learning Resources | C9: 100 | D9: =SUM('Autonomous 107m'!M28:M33) -> 80 | E9: =D9/C9 -> 0.8 | G9: 2.76-3.00 | H9: B++ | I9: Accredited
A10: 5 | B10: Student Support and Progression | C10: 140 | D10: =SUM('Autonomous 107m'!M34:M42) -> 34 | E10: =D10/C10 -> 0.24285714 | G10: 2.51-2.75 | H10: B+ | I10: Accredited
A11: 6 | B11: Governance, Leadership and Management | C11: 100 | D11: =SUM('Autonomous 107m'!M43:M51) -> 60 | E11: =D11/C11 -> 0.6 | G11: 2.01-2.50 | H11: B | I11: Accredited
A12: 7 | B12: Institutional Values and Best Practices | C12: 100 | D12: =SUM('Autonomous 107m'!M52:M57) -> 20 | E12: =D12/C12 -> 0.2 | G12: 1.51-2.00 | H12: C | I12: Accredited
C13: =SUM(C6:C12) -> 1000 | D13: =SUM(D6:D12) -> 674 | E13: =D13/C13 -> 0.674 | G13: ≤ 1.50 | H13: D | I13: Not Accredited
D14: Grade | E14: =IF(AND($E$13<=4,$E$13>=3.51),"A++",IF(AND($E$13<=3.5,$E$13>=3.26),"A+",IF(AND($E$13<=3.25,$E$13>3.01),"A",IF(AND($E$13<=3,$E$13>=2.76),"B++",IF(AND($E$13<=2.75,$E$13>=2.51),"B+",IF(AND($E$13<=2.5,$E$13>=2.01),"B",IF(AND($E$13<=2,$E$13>=1.51),"C","D"))))))) -> D
A16: No | B16: Criteria and Key Indicators | C16: Key Indicator Weightage (Wi) | D16: Key Indicator Wise Weighted Grade Points (KIWGP)i | E16: Key Indicator wise Grade Point Averages (CrWGPi/Wi)
A17: Criterion 1: Curricular Aspects
A18: 1.1 | B18: Curriculum Planning and Implementation | C18: 20 | D18: =SUM('Autonomous 107m'!L3) -> 0
A19: 1.2 | B19: Academic Flexibility | C19: 30 | D19: =SUM('Autonomous 107m'!L4:L5) -> 120
A20: 1.3 | B20: 1.3 Curriculum Enrichment | C20: 30 | D20: =SUM('Autonomous 107m'!L6:L7) -> 100
A21: 1.4 | B21: 1.4 Feedback System | C21: 20 | D21: =SUM('Autonomous 107m'!L8) -> 0
C22: =SUM(C18:C21) -> 100 | D22: =SUM(D18:D21) -> 220
D23: Grade | E23: *
A24: Criterion 2: Teaching-learning and Evaluation
A25: 2.1 | B25: Student Enrollment and Profile | C25: 40 | D25: =SUM('Autonomous 107m'!L9:L10) -> 50
A26: 2.2 | B26: Catering to Student Diversity | C26: 40 | D26: =SUM('Autonomous 107m'!L11) -> 0
A27: 2.3 | B27: Teaching- Learning Process | C27: 40 | D27: =SUM('Autonomous 107m'!L12) -> 30
A28: 2.4 | B28: Teacher Profile and Quality | C28: 40 | D28: =SUM('Autonomous 107m'!L13:L14) -> 60
A29: 2.5 | B29: Evaluation Process and Reforms | C29: 40 | D29: =SUM('Autonomous 107m'!L15) -> 40
A30: 2.6 | B30: Student Performance and Learning Outcomes | C30: 90 | D30: =SUM('Autonomous 107m'!L16:L17) -> 0
A31: 2.7 | B31: Student Satisfaction Survey | C31: 60 | D31: =SUM('Autonomous 107m'!L18) -> 0
C32: =SUM(C25:C31) -> 350 | D32: =SUM(D25:D31) -> 180
D33: Grade | E33: =IF(AND($E$32<=4,$E$32>=3.51),"A++",IF(AND($E$32<=3.5,$E$32>=3.26),"A+",IF(AND($E$32<=3.25,$E$32>3.01),"A",IF(AND($E$32<=3,$E$32>=2.76),"B++",IF(AND($E$32<=2.75,$E$32>=2.51),"B+",IF(AND($E$32<=2.5,$E$32>=2.01),"B",IF(AND($E$32<=2,$E$32>=1.51),"C","D"))))))) -> D
A34: Criterion 3: Research, Innovations and Extension
A35: 3.1 | B35: Resource Mobilization for Research | C35: 10 | D35: =SUM('Autonomous 107m'!L19) -> 0
A36: 3.2 | B36: Innovation Ecosystem | C36: 15 | D36: =SUM('Autonomous 107m'!L20:L21) -> 0
A37: 3.3 | B37: Research Publications and Awards | C37: 25 | D37: =SUM('Autonomous 107m'!L22:L23) -> 60
A38: 3.4 | B38: Extension Activities | C38: 40 | D38: =SUM('Autonomous 107m'!L24:L26) -> 20
A39: 3.5 | B39: Collaboration | C39: 20 | D39: =SUM('Autonomous 107m'!L27) -> 0
C40: =SUM(C35:C39) -> 110 | D40: =SUM(D35:D39) -> 80
D41: Grade | E41: =IF(AND($E$47<=4,$E$47>=3.51),"A++",IF(AND($E$47<=3.5,$E$47>=3.26),"A+",IF(AND($E$47<=3.25,$E$47>3.01),"A",IF(AND($E$47<=3,$E$47>=2.76),"B++",IF(AND($E$47<=2.75,$E$47>=2.51),"B+",IF(AND($E$47<=2.5,$E$47>=2.01),"B",IF(AND($E$47<=2,$E$47>=1.51),"C","D"))))))) -> D
A42: Criterion 4: Infrastructure and Learning Resources
A43: 4.1 | B43: Physical Facilities | C43: 30 | D43: =SUM('Autonomous 107m'!L28:L29) -> 0
A44: 4.2 | B44: Library as a Learning Resource | C44: 20 | D44: =SUM('Autonomous 107m'!L30) -> 80
A45: 4.3 | B45: IT Infrastructure | C45: 30 | D45: =SUM('Autonomous 107m'!L31:L32) -> 0
...

Sheet Qn (72m)
J1: Response | K1: Autonomous
A2: S. No | B2: Criteria © | C2: Key Indicator (KI) | D2: Metric (M) Type | E2: Metric (M) Num | F2: Metric (M) Description | G2: M Wt | H2: KI Wt | I2: © Wt | J2: Institute Name | K2: Metric Grade scale (0-4) | L2: M wise weighted Grade points | M2: KIwise weighted Grade points | N2: KIwise weighted Grade points Average | O2: ©Wise Weighted Average | P2: ©Wise Weighted Grade Point Average
A3: 1 | B3: 1. Curricular Aspects | C3: 1.2 Academic Flexibility | D3: QnM | E3: 1.1.2 | F3: Percentage of Programmes where syllabus revision was carried out during the last five years 1.1.2.1: How many Programmes were revised out of total number of Programmes offered during the same period within last five years? 1.1.2.2 : Number of all Programmes offered by the institution during the last five years | G3: 20 | H3: 30 | I3: 120 | J3: =VLOOKUP(E3,'Autonomous 107m'!$E$3:$J$109,6,0) -> 92.86 | K3: =IF(J3>80,4,IF(AND(J3<=80,J3>60),3,IF(AND(J3<=60,J3>40),2,IF(AND(J3<=40,J3>20),1,IF(J3<=20,0))))) -> 4 | L3: =K3*G3 -> 80 | M3: 120 | N3: =M3/H3 -> 4 | O3: =SUM(M3:M11) -> 410 | P3: =O3/I3 -> 3.4166667
A4: 2 | B4: 1. Curricular Aspects | C4: 1.2 Academic Flexibility | D4: QnM | E4: 1.1.3 | F4: Average percentage of courses having focus on employability/ entrepreneurship/ skill development offered by the institution during the last five years 1.1.3.1: Number of courses having focus on employability/ entrepreneurship/ skill development year wise during last five years | G4: 10 | J4: =VLOOKUP(E4,'Autonomous 107m'!$E$3:$J$109,6,0) -> 84.19 | K4: =IF(J4>80,4,IF(AND(J4<=80,J4>60),3,IF(AND(J4<=60,J4>40),2,IF(AND(J4<=40,J4>20),1,IF(J4<=20,0))))) -> 4 | L4: =K4*G4 -> 40
A5: 3 | B5: 1. Curricular Aspects | C5: 1.3 Curriculum Enrichment | D5: QnM | E5: 1.2.1 | F5: Percentage of new courses introduced of the total number of courses across all programs offered during the last five years 1.2.1.1: How many new courses are introduced within the last five years 1.2.1.2 : Number of courses offered by the institution across all Programmes during the last five years | G5: 20 | H5: 40 | J5: =VLOOKUP(E5,'Autonomous 107m'!$E$3:$J$109,6,0) -> 38.71 | K5: =IF(J5>80,4,IF(AND(J5<=80,J5>60),3,IF(AND(J5<=60,J5>40),2,IF(AND(J5<=40,J5>20),1,IF(J5<=20,0))))) -> 1 | L5: =K5*G5 -> 20 | M5: 160 | N5: =M5/H5 -> 4
A6: 4 | B6: 1. Curricular Aspects | C6: 1.4 Feedback System | D6: QnM | E6: 1.2.2 | F6: Percentage of Programmes in which Choice Based Credit System (CBCS)/elective course system has been implemented (Data for the latest completed academic year ) 1.2.2.1: Number of Programmes in which CBCS/Elective course system implemented. | G6: 20 | J6: =VLOOKUP(E6,'Autonomous 107m'!$E$3:$J$109,6,0) -> 81.25 | K6: =IF(J6>80,4,IF(AND(J6<=80,J6>60),3,IF(AND(J6<=60,J6>40),2,IF(AND(J6<=40,J6>20),1,IF(J6<=20,0))))) -> 4 | L6: =K6*G6 -> 80
A7: 5 | B7: 2. Teaching-Learning and Evaluation | C7: 2.1 Student Enrolment and Profile | D7: QnM | E7: 1.3.2 | F7: Number of value-added courses for imparting transferable and life skills offered during last five years 1.3.2.1: How many new value-added courses are added within the last 5 years | G7: 10 | H7: 30 | J7: =VLOOKUP(E7,'Autonomous 107m'!$E$3:$J$109,6,0) -> 87 | K7: =IF(J7>80,4,IF(AND(J7<=80,J7>60),3,IF(AND(J7<=60,J7>40),2,IF(AND(J7<=40,J7>20),1,IF(J7<=20,0))))) -> 4 | L7: =K7*G7 -> 40 | M7: 80 | N7: =M7/H7 -> 2.6666667
A8: 6 | B8: 2. Teaching-Learning and Evaluation | C8: 2.1 Student Enrolment and Profile | D8: QnM | E8: 1.3.3 | F8: Average Percentage of students enrolled in the courses under 1.3.2 above 1.3.3.1: Number of students enrolled in value added courses (beyond the curriculum) offered year wise during last five year | G8: 10 | J8: =VLOOKUP(E8,'Autonomous 107m'!$E$3:$J$109,6,0) -> 32.64 | K8: =IF(J8>80,4,IF(AND(J8<=80,J8>60),3,IF(AND(J8<=60,J8>40),2,IF(AND(J8<=40,J8>20),1,IF(J8<=20,0))))) -> 1 | L8: =K8*G8 -> 10
A9: 7 | B9: 2. Teaching-Learning and Evaluation | C9: 2.2 Student Teacher Ratio | D9: QnM | E9: 1.3.4 | F9: Percentage of students undertaking field projects/ internships / student projects (Data for the latest completed academic year) 1.3.4.1: Number of students undertaking field projects / internships / student projects | G9: 10 | J9: =VLOOKUP(E9,'Autonomous 107m'!$E$3:$J$109,6,0) -> 61.81 | K9: =IF(J9>80,4,IF(AND(J9<=80,J9>60),3,IF(AND(J9<=60,J9>40),2,IF(AND(J9<=40,J9>20),1,IF(J9<=20,0))))) -> 3 | L9: =K9*G9 -> 30
A10: 8 | B10: 2. Teaching-Learning and Evaluation | C10: 2.4 Teacher Profile and Quality | D10: QnM | E10: 1.4.1 | F10: Structured feedback for design and review of syllabus ( semester wise / year wise) is obtained from 1) Students, 2) Teachers, 3) Employers, 4) Alumni | G10: 10 | H10: 20 | J10: =VLOOKUP(E10,'Autonomous 107m'!$E$3:$J$109,6,0) -> B | K10: =IF(EXACT(J10,"A"),4,IF(EXACT(J10,"B"),3,IF(EXACT(J10,"C"),2,IF(EXACT(J10,"D"),1,0)))) -> 3 | L10: =K10*G10 -> 30 | M10: 50 | N10: =M10/H10 -> 2.5
A11: 9 | B11: 2. Teaching-Learning and Evaluation | C11: 2.4 Teacher Profile and Quality | D11: QnM | E11: 1.4.2 | F11: The feedback system of the Institution comprises of the following : A. Feedback collected, analysed and action taken and report made available on website B. Feedback collected, analysed and action taken C. Feedback collected and analysed D. Feedback collected E. Feedback not obtained | G11: 10 | J11: =VLOOKUP(E11,'Autonomous 107m'!$E$3:$J$109,6,0) -> C | K11: =IF(EXACT(J11,"A"),4,IF(EXACT(J11,"B"),3,IF(EXACT(J11,"C"),2,IF(EXACT(J11,"D"),1,0)))) -> 2 | L11: =K11*G11 -> 20
A12: 10 | B12: 2. Teaching-Learning and Evaluation | C12: 2.6 Student Performance and Learning Outcomes | D12: QnM | E12: 2.1.1 | F12: Average Enrolment percentage (Average of last five years) 2.1.1.1: Number of students admitted year wise during last five years 2.1.1.2: Number of sanctioned seats year wise during last five years | G12: 10 | H12: 20 | I12: 200 | J12: =VLOOKUP(E12,'Autonomous 107m'!$E$3:$J$109,6,0) -> 85.42 | K12: =IF(J12>80,4,IF(AND(J12<=80,J12>60),3,IF(AND(J12<=60,J12>40),2,IF(AND(J12<=40,J12>20),1,IF(J12<=20,0))))) -> 4 | L12: =K12*G12 -> 40 | M12: 80 | N12: =M12/H12 -> 4 | O12: =SUM(M12:M22) -> 619 | P12: =O12/I12 -> 3.095
A13: 11 | B13: 2. Teaching-Learning and Evaluation | C13: 2.7 Student Satisfaction Survey | D13: QnM | E13: 2.1.2 | F13: Average percentage of seats filled against reserved categories (SC, ST, OBC, Divyangjan, etc. as per applicable reservation policy ) during the last five years ( exclusive of supernumerary seats) 2.1.2.1: Number of actual students admitted from the reserved categories year wise during last five years | G13: 10 | J13: =VLOOKUP(E13,'Autonomous 107m'!$E$3:$J$109,6,0) -> 97.91 | K13: =IF(J13>80,4,IF(AND(J13<=80,J13>60),3,IF(AND(J13<=60,J13>40),2,IF(AND(J13<=40,J13>20),1,IF(J13<=20,0))))) -> 4 | L13: =K13*G13 -> 40
A14: 12 | B14: 3. Research, Innovations and Extension | C14: 3.1 Resource Mobilization for Research | D14: QnM | E14: 2.2.2 | F14: Student - Full time teacher ratio (Data for the latest completed academic year) | G14: 15 | H14: 15 | J14: =VLOOKUP(E14,'Autonomous 107m'!$E$3:$J$109,6,0) -> 16.13 | K14: =IF(J14>80,4,IF(AND(J14<=80,J14>60),3,IF(AND(J14<=60,J14>40),2,IF(AND(J14<=40,J14>20),1,IF(J14<=20,0))))) -> 0 | L14: =K14*G14 -> 0 | M14: 45 | N14: =M14/H14 -> 3
A15: 13 | B15: 3. Research, Innovations and Extension | C15: 3.2 Innovation Ecosystem | D15: QnM | E15: 2.3.3 | F15: Ratio of students to mentor for academic and other related issues (Data for the latest completed academic year ) 2.3.3.1: Number of mentors Number of students assigned to each Mentor | G15: 10 | H15: 10 | J15: =VLOOKUP(E15,'Autonomous 107m'!$E$3:$J$109,6,0) -> 0.79236111 | K15: =IF(J15>80,4,IF(AND(J15<=80,J15>60),3,IF(AND(J15<=60,J15>40),2,IF(AND(J15<=40,J15>20),1,IF(J15<=20,0))))) -> 0 | L15: =K15*G15 -> 0 | M15: 30 | N15: =M15/H15 -> 3
A16: 14 | B16: 3. Research, Innovations and Extension | C16: 3.3 Research Publications and Awards | D16: QnM | E16: 2.4.1 | F16: Average percentage of full time teachers against sanctioned posts during the last five years | G16: 15 | H16: 50 | J16: =VLOOKUP(E16,'Autonomous 107m'!$E$3:$J$109,6,0) -> 99.34 | K16: =IF(J16>80,4,IF(AND(J16<=80,J16>60),3,IF(AND(J16<=60,J16>40),2,IF(AND(J16<=40,J16>20),1,IF(J16<=20,0))))) -> 4 | L16: =K16*G16 -> 60 | M16: 110 | N16: =M16/H16 -> 2.2
A17: 15 | B17: 3. Research, Innovations and Extension | C17: 3.3 Research Publications and Awards | D17: QnM | E17: 2.4.2 | F17: Average percentage of full time teachers with Ph.D. / D.M. / M.Ch. / D.N.B Super speciality / D.Sc. / D.Litt. during the last five years 2.4.2.1: Number of full time teachers with Ph.D./ D.M. / M.Ch. / D.N.B Super speciality / D.Sc. / D.Litt. year wise during last five years | G17: 20 | J17: =VLOOKUP(E17,'Autonomous 107m'!$E$3:$J$109,6,0) -> 11.09 | K17: =IF(J17>80,4,IF(AND(J17<=80,J17>60),3,IF(AND(J17<=60,J17>40),2,IF(AND(J17<=40,J17>20),1,IF(J17<=20,0))))) -> 0 | L17: =K17*G17 -> 0
A18: 16 | B18: 3. Research, Innovations and Extension | C18: 3.4 Extension Activities | D18: QnM | E18: 2.4.3 | F18: Average teaching experience of full time teachers in the same institution (Data for the latest completed academic year in number of years 2.4.3.1: Total experience of full-time teachers | G18: 15 | J18: =VLOOKUP(E18,'Autonomous 107m'!$E$3:$J$109,6,0) -> 5.69 | K18: =IF(J18>80,4,IF(AND(J18<=80,J18>60),3,IF(AND(J18<=60,J18>40),2,IF(AND(J18<=40,J18>20),1,IF(J18<=20,0))))) -> 0 | L18: =K18*G18 -> 0
A19: 17 | B19: 3. Research, Innovations and Extension | C19: 3.5 Collaboration | D19: QnM | E19: 2.5.1 | F19: Average number of days from the date of last semester-end/ year- end examination till the declaration of results during the last five years 2.5.1.1: Number of days from the date of last semester-end/ year- end examination till the declaration of results year wise during the last five years | G19: 20 | H19: 35 | J19: =VLOOKUP(E19,'Autonomous 107m'!$E$3:$J$109,6,0) -> 21 | K19: =IF(J19>80,4,IF(AND(J19<=80,J19>60),3,IF(AND(J19<=60,J19>40),2,IF(AND(J19<=40,J19>20),1,IF(J19<=20,0))))) -> 1 | L19: =K19*G19 -> 20 | M19: 100 | N19: =M19/H19 -> 2.8571429
A20: 18 | B20: 4. Infrastructure and Learning Resources | C20: 4.1 Physical Facilities | D20: QnM | E20: 2.5.2 | F20: Average percentage of student complaints/grievances about evaluation against total number appeared in the examinations during the last five years 2.5.2.1: Number of complaints/grievances about evaluation year wise during last five years | G20: 15 | J20: =VLOOKUP(E20,'Autonomous 107m'!$E$3:$J$109,6,0) -> 12.61 | K20: =IF(J20>80,4,IF(AND(J20<=80,J20>60),3,IF(AND(J20<=60,J20>40),2,IF(AND(J20<=40,J20>20),1,IF(J20<=20,0))))) -> 0 | L20: =K20*G20 -> 0
A21: 19 | B21: 4. Infrastructure and Learning Resources | C21: 4.3 IT Infrastructure | D21: QnM | E21: 2.6.3 | F21: Pass percentage of students (Data for the latest completed academic year) 2.6.3.1: Total number of final year students who passed the examination conducted by Institution. 2.6.3.2: Total number of final year students who appeared for the examination | G21: 20 | H21: 20 | J21: =VLOOKUP(E21,'Autonomous 107m'!$E$3:$J$109,6,0) -> 90.9 | K21: =IF(J21>80,4,IF(AND(J21<=80,J21>60),3,IF(AND(J21<=60,J21>40),2,IF(AND(J21<=40,J21>20),1,IF(J21<=20,0))))) -> 4 | L21: =K21*G21 -> 80 | M21: 80 | N21: =M21/H21 -> 4
A22: 20 | B22: 4. Infrastructure and Learning Resources | C22: 4.4 Maintenance of Campus Infrastructure | D22: QnM | E22: 2.7.1 | F22: Online student satisfaction survey regarding to teaching learning process. (Online survey to be conducted) | G22: 50 | H22: 50 | J22: =VLOOKUP(E22,'Autonomous 107m'!$E$3:$J$109,6,0) -> 3.48 | K22: =IF(J22>80,4,IF(AND(J22<=80,J22>60),3,IF(AND(J22<=60,J22>40),2,IF(AND(J22<=40,J22>20),1,IF(J22<=20,0))))) -> 0 | L22: =K22*G22 -> 0 | M22: 174 | N22: =M22/H22 -> 3.48
A23: 21 | B23: 5. Student Support and Progression | C23: 5.1 Student Support | D23: QnM | E23: 3.1.2 | F23: The institution provides seed money to its teachers for research (Average per year) 3.1.2.1: The amount of seed money provided by institution to its teachers for research year wise during last five years (INR in lakhs) | G23: 8 | H23: 14 | I23: 129 | J23: =VLOOKUP(E23,'Autonomous 107m'!$E$3:$J$109,6,0) -> 0 | K23: =IF(J23>80,4,IF(AND(J23<=80,J23>60),3,IF(AND(J23<=60,J23>40),2,IF(AND(J23<=40,J23>20),1,IF(J23<=20,0))))) -> 0 | L23: =K23*G23 -> 0 | M23: 0 | N23: =M23/H23 -> 0 | O23: =SUM(M23:M42) -> 207 | P23: =O23/I23 -> 1.6046512
A24: 22 | B24: 5. Student Support and Progression | C24: 5.1 Student Support | D24: QnM | E24: 3.1.3 | F24: Percentage of teachers awarded national / international fellowship for advanced studies/research during the last five years 3.1.3.1: The number of teachers awarded national / international fellowship for advanced studies / research year wise during last five years | G24: 6 | J24: =VLOOKUP(E24,'Autonomous 107m'!$E$3:$J$109,6,0) -> 0.06 | K24: =IF(J24>80,4,IF(AND(J24<=80,J24>60),3,IF(AND(J24<=60,J24>40),2,IF(AND(J24<=40,J24>20),1,IF(J24<=20,0))))) -> 0 | L24: =K24*G24 -> 0
A25: 23 | B25: 5. Student Support and Progression | C25: 5.1 Student Support | D25: QnM | E25: 3.2.1 | F25: Grants received from Government and non-governmental agencies for research projects, endowments, Chairs in the institution during the last five years (INR in Lakhs) 3.2.1.1: Total Grants from Government and non-governmental agencies for research projects , endowments, Chairs in the institution during the last five years (INR in Lakhs) | G25: 2 | H25: 10 | J25: =VLOOKUP(E25,'Autonomous 107m'!$E$3:$J$109,6,0) -> 116.67 | K25: =IF(J25>80,4,IF(AND(J25<=80,J25>60),3,IF(AND(J25<=60,J25>40),2,IF(AND(J25<=40,J25>20),1,IF(J25<=20,0))))) -> 4 | L25: =K25*G25 -> 8 | M25: 17 | N25: =M25/H25 -> 1.7
A26: 24 | B26: 5. Student Support and Progression | C26: 5.1 Student Support | D26: QnM | E26: 3.2.2 | F26: Percentage of teachers having research projects during the last five years 3.2.2.1: Number of teachers having research projects during the last five years | G26: 2 | J26: =VLOOKUP(E26,'Autonomous 107m'!$E$3:$J$109,6,0) -> 1.02 | K26: =IF(J26>80,4,IF(AND(J26<=80,J26>60),3,IF(AND(J26<=60,J26>40),2,IF(AND(J26<=40,J26>20),1,IF(J26<=20,0))))) -> 0 | L26: =K26*G26 -> 0
A27: 25 | B27: 5. Student Support and Progression | C27: 5.2 Student Progression | D27: QnM | E27: 3.2.3 | F27: Percentage of teachers recognised as research guides 3.2.3.1: Number of teachers recognised as research guides | G27: 3 | J27: =VLOOKUP(E27,'Autonomous 107m'!$E$3:$J$109,6,0) -> 3.03 | K27: =IF(J27>80,4,IF(AND(J27<=80,J27>60),3,IF(AND(J27<=60,J27>40),2,IF(AND(J27<=40,J27>20),1,IF(J27<=20,0))))) -> 0 | L27: =K27*G27 -> 0
A28: 26 | B28: 5. Student Support and Progression | C28: 5.2 Student Progression | D28: QnM | E28: 3.2.4 | F28: Average percentage of departments having Research projects funded by government and non-government agencies during the last five years 3.2.4.1: Number of departments having Research projects funded by government and non-government agencies during the last five years | G28: 3 | J28: =VLOOKUP(E28,'Autonomous 107m'!$E$3:$J$109,6,0) -> 43.57 | K28: =IF(J28>80,4,IF(AND(J28<=80,J28>60),3,IF(AND(J28<=60,J28>40),2,IF(AND(J28<=40,J28>20),1,IF(J28<=20,0))))) -> 2 | L28: =K28*G28 -> 6
A29: 27 | B29: 5. Student Support and Progression | C29: 5.3 Student Participation and Activities | D29: QnM | E29: 3.3.2 | F29: Number of workshops/seminars conducted on Research Methodology, Intellectual Property Rights (IPR), entrepreneurship and skills development during the last five years 3.3.2.1: Total number of workshops/seminars conducted on Research Methodology, Intellectual Property Rights (IPR) and entrepreneurship and skills development year wise during last five years | G29: 5 | H29: 5 | J29: =VLOOKUP(E29,'Autonomous 107m'!$E$3:$J$109,6,0) -> 43 | K29: =IF(J29>80,4,IF(AND(J29<=80,J29>60),3,IF(AND(J29<=60,J29>40),2,IF(AND(J29<=40,J29>20),1,IF(J29<=20,0))))) -> 2 | L29: =K29*G29 -> 10 | M29: 15 | N29: =M29/H29 -> 3
